Workbook

Sheet ENTRY DATA
B3: SLOT | C3: PLAYER NAME | F3: CLAN NAME
A4: NUMBER | C4: PROFESSIONAL | D4: IN - GAME | F4: TEAM NAME | G4: CLAN | J4: GENDER | K4: REGION | L4: COUNTRY | M4: DEVICE | N4: D.MODEL
A5: 1 | B5: 1
B13: 2
B21: 3
B29: 4
B37: 5

Sheet DAY 1
R2: GAMES STATS II ( DAMAGES & ACCURACY )
H3: GAMES | L3: DAILY TOTAL | R3: LOBBY 1 | T3: LOBBY 2 | V3: LOBBY 3 | Y3: TOTAL | AB3: AVERAGE
C4: PLAYER NAME | D4: TEAM NAME | E4: SLOT | H4: LOBBY 1 | I4: LOBBY 2 | J4: LOBBY 3 | L4: MATCHES | M4: KILLS | P4: PLAYER NAME | R4: DAMAGE | S4: ACCURCY | T4: DAMAGE | U4: ACCURCY | V4: DAMAGE | W4: ACCURCY | Y4: DAMAGE | Z4: ACCURACY | AB4: DAMAGE | AC4: ACCURACY
C5: =IF(AND('ENTRY DATA'!D5=""),"",('ENTRY DATA'!D5)) | D5: =IF(AND('ENTRY DATA'!F5=""),"",('ENTRY DATA'!F5)) | E5: =IF(AND('ENTRY DATA'!B5=""),"",('ENTRY DATA'!B5)) -> 1 | L5: =COUNT(H5:J5) -> 0 | M5: =IF(AND(H5="",I5="",J5=""),"",(H5+I5+J5)) | P5: =C5 | Y5: =IF(AND(R5="",T5="",V5=""),"",SUM(R5,T5,V5)) | Z5: =IF(AND(S5="",U5="",W5=""),"",SUM(S5,U5,W5)) | AB5: =Y5/L5 -> #VALUE! | AC5: =Z5/L5 -> #VALUE!
C6: =IF(AND('ENTRY DATA'!D6=""),"",('ENTRY DATA'!D6)) | D6: =IF(AND('ENTRY DATA'!F6=""),"",('ENTRY DATA'!F6)) | E6: =IF(AND('ENTRY DATA'!B6=""),"",('ENTRY DATA'!B6)) | L6: =COUNT(H6:J6) -> 0 | M6: =IF(AND(H6="",I6="",J6=""),"",(H6+I6+J6)) | P6: =C6 | Y6: =IF(AND(R6="",T6="",V6=""),"",SUM(R6,T6,V6)) | Z6: =IF(AND(S6="",U6="",W6=""),"",SUM(S6,U6,W6)) | AB6: =Y6/L6 -> #VALUE! | AC6: =Z6/L6 -> #VALUE!
C7: =IF(AND('ENTRY DATA'!D7=""),"",('ENTRY DATA'!D7)) | D7: =IF(AND('ENTRY DATA'!F7=""),"",('ENTRY DATA'!F7)) | E7: =IF(AND('ENTRY DATA'!B7=""),"",('ENTRY DATA'!B7)) | L7: =COUNT(H7:J7) -> 0 | M7: =IF(AND(H7="",I7="",J7=""),"",(H7+I7+J7)) | P7: =C7 | Y7: =IF(AND(R7="",T7="",V7=""),"",SUM(R7,T7,V7)) | Z7: =IF(AND(S7="",U7="",W7=""),"",SUM(S7,U7,W7)) | AB7: =Y7/L7 -> #VALUE! | AC7: =Z7/L7 -> #VALUE!
C8: =IF(AND('ENTRY DATA'!D8=""),"",('ENTRY DATA'!D8)) | D8: =IF(AND('ENTRY DATA'!F8=""),"",('ENTRY DATA'!F8)) | E8: =IF(AND('ENTRY DATA'!B8=""),"",('ENTRY DATA'!B8)) | L8: =COUNT(H8:J8) -> 0 | M8: =IF(AND(H8="",I8="",J8=""),"",(H8+I8+J8)) | P8: =C8 | Y8: =IF(AND(R8="",T8="",V8=""),"",SUM(R8,T8,V8)) | Z8: =IF(AND(S8="",U8="",W8=""),"",SUM(S8,U8,W8)) | AB8: =Y8/L8 -> #VALUE! | AC8: =Z8/L8 -> #VALUE!
C9: =IF(AND('ENTRY DATA'!D9=""),"",('ENTRY DATA'!D9)) | D9: =IF(AND('ENTRY DATA'!F9=""),"",('ENTRY DATA'!F9)) | E9: =IF(AND('ENTRY DATA'!B9=""),"",('ENTRY DATA'!B9)) | L9: =COUNT(H9:J9) -> 0 | M9: =IF(AND(H9="",I9="",J9=""),"",(H9+I9+J9)) | P9: =C9 | Y9: =IF(AND(R9="",T9="",V9=""),"",SUM(R9,T9,V9)) | Z9: =IF(AND(S9="",U9="",W9=""),"",SUM(S9,U9,W9)) | AB9: =Y9/L9 -> #VALUE! | AC9: =Z9/L9 -> #VALUE!
C10: =IF(AND('ENTRY DATA'!D10=""),"",('ENTRY DATA'!D10)) | D10: =IF(AND('ENTRY DATA'!F10=""),"",('ENTRY DATA'!F10)) | E10: =IF(AND('ENTRY DATA'!B10=""),"",('ENTRY DATA'!B10)) | L10: =COUNT(H10:J10) -> 0 | M10: =IF(AND(H10="",I10="",J10=""),"",(H10+I10+J10)) | P10: =C10 | Y10: =IF(AND(R10="",T10="",V10=""),"",SUM(R10,T10,V10)) | Z10: =IF(AND(S10="",U10="",W10=""),"",SUM(S10,U10,W10)) | AB10: =Y10/L10 -> #VALUE! | AC10: =Z10/L10 -> #VALUE!
C11: =IF(AND('ENTRY DATA'!D11=""),"",('ENTRY DATA'!D11)) | D11: =IF(AND('ENTRY DATA'!F11=""),"",('ENTRY DATA'!F11)) | E11: =IF(AND('ENTRY DATA'!B11=""),"",('ENTRY DATA'!B11)) | L11: =COUNT(H11:J11) -> 0 | M11: =IF(AND(H11="",I11="",J11=""),"",(H11+I11+J11)) | P11: =C11 | Y11: =IF(AND(R11="",T11="",V11=""),"",SUM(R11,T11,V11)) | Z11: =IF(AND(S11="",U11="",W11=""),"",SUM(S11,U11,W11)) | AB11: =Y11/L11 -> #VALUE! | AC11: =Z11/L11 -> #VALUE!
C12: =IF(AND('ENTRY DATA'!D12=""),"",('ENTRY DATA'!D12)) | D12: =IF(AND('ENTRY DATA'!F12=""),"",('ENTRY DATA'!F12)) | E12: =IF(AND('ENTRY DATA'!B12=""),"",('ENTRY DATA'!B12)) | L12: =COUNT(H12:J12) -> 0 | M12: =IF(AND(H12="",I12="",J12=""),"",(H12+I12+J12)) | P12: =C12 | Y12: =IF(AND(R12="",T12="",V12=""),"",SUM(R12,T12,V12)) | Z12: =IF(AND(S12="",U12="",W12=""),"",SUM(S12,U12,W12)) | AB12: =Y12/L12 -> #VALUE! | AC12: =Z12/L12 -> #VALUE!
C13: =IF(AND('ENTRY DATA'!D13=""),"",('ENTRY DATA'!D13)) | D13: =IF(AND('ENTRY DATA'!F13=""),"",('ENTRY DATA'!F13)) | E13: =IF(AND('ENTRY DATA'!B13=""),"",('ENTRY DATA'!B13)) -> 2 | L13: =COUNT(H13:J13) -> 0 | M13: =IF(AND(H13="",I13="",J13=""),"",(H13+I13+J13)) | P13: =C13 | Y13: =IF(AND(R13="",T13="",V13=""),"",SUM(R13,T13,V13)) | Z13: =IF(AND(S13="",U13="",W13=""),"",SUM(S13,U13,W13)) | AB13: =Y13/L13 -> #VALUE! | AC13: =Z13/L13 -> #VALUE!
C14: =IF(AND('ENTRY DATA'!D14=""),"",('ENTRY DATA'!D14)) | D14: =IF(AND('ENTRY DATA'!F14=""),"",('ENTRY DATA'!F14)) | E14: =IF(AND('ENTRY DATA'!B14=""),"",('ENTRY DATA'!B14)) | L14: =COUNT(H14:J14) -> 0 | M14: =IF(AND(H14="",I14="",J14=""),"",(H14+I14+J14)) | P14: =C14 | Y14: =IF(AND(R14="",T14="",V14=""),"",SUM(R14,T14,V14)) | Z14: =IF(AND(S14="",U14="",W14=""),"",SUM(S14,U14,W14)) | AB14: =Y14/L14 -> #VALUE! | AC14: =Z14/L14 -> #VALUE!
C15: =IF(AND('ENTRY DATA'!D15=""),"",('ENTRY DATA'!D15)) | D15: =IF(AND('ENTRY DATA'!F15=""),"",('ENTRY DATA'!F15)) | E15: =IF(AND('ENTRY DATA'!B15=""),"",('ENTRY DATA'!B15)) | L15: =COUNT(H15:J15) -> 0 | M15: =IF(AND(H15="",I15="",J15=""),"",(H15+I15+J15)) | P15: =C15 | Y15: =IF(AND(R15="",T15="",V15=""),"",SUM(R15,T15,V15)) | Z15: =IF(AND(S15="",U15="",W15=""),"",SUM(S15,U15,W15)) | AB15: =Y15/L15 -> #VALUE! | AC15: =Z15/L15 -> #VALUE!
C16: =IF(AND('ENTRY DATA'!D16=""),"",('ENTRY DATA'!D16)) | D16: =IF(AND('ENTRY DATA'!F16=""),"",('ENTRY DATA'!F16)) | E16: =IF(AND('ENTRY DATA'!B16=""),"",('ENTRY DATA'!B16)) | L16: =COUNT(H16:J16) -> 0 | M16: =IF(AND(H16="",I16="",J16=""),"",(H16+I16+J16)) | P16: =C16 | Y16: =IF(AND(R16="",T16="",V16=""),"",SUM(R16,T16,V16)) | Z16: =IF(AND(S16="",U16="",W16=""),"",SUM(S16,U16,W16)) | AB16: =Y16/L16 -> #VALUE! | AC16: =Z16/L16 -> #VALUE!
... C300: =IF(AND('ENTRY DATA'!D300=""),"",('ENTRY DATA'!D300)) | D300: =IF(AND('ENTRY DATA'!F300=""),"",('ENTRY DATA'!F300)) | E300: =IF(AND('ENTRY DATA'!B300=""),"",('ENTRY DATA'!B300)) | L300: =COUNT(H300:J300) -> 0 | M300: =IF(AND(H300="",I300="",J300=""),"",(H300+I300+J300)) | P300: =C300 | Y300: =IF(AND(R300="",T300="",V300=""),"",SUM(R300,T300,V300)) | Z300: =IF(AND(S300="",U300="",W300=""),"",SUM(S300,U300,W300)) | AB300: =Y300/L300 -> #VALUE! | AC300: =Z300/L300 -> #VALUE!
P301: =C301 -> 0 | Y301: =IF(AND(R301="",T301="",V301=""),"",SUM(R301,T301,V301)) | Z301: =IF(AND(S301="",U301="",W301=""),"",SUM(S301,U301,W301)) | AB301: =Y301/L301 -> #VALUE! | AC301: =Z301/L301 -> #VALUE!
Y302: =IF(AND(R302="",T302="",V302=""),"",SUM(R302,T302,V302)) | Z302: =IF(AND(S302="",U302="",W302=""),"",SUM(S302,U302,W302))

Sheet DAY 2
R2: GAMES STATS II ( DAMAGES & ACCURACY )
H3: GAMES | L3: DAILY TOTAL | R3: LOBBY 1 | T3: LOBBY 2 | V3: LOBBY 3 | Y3: TOTAL | AB3: AVERAGE
C4: PLAYER NAME | D4: TEAM NAME | E4: SLOT | H4: LOBBY 1 | I4: LOBBY 2 | J4: LOBBY 3 | L4: MATCHES | M4: KILLS | P4: PLAYER NAME | R4: DAMAGE | S4: ACCURCY | T4: DAMAGE | U4: ACCURCY | V4: DAMAGE | W4: ACCURCY | Y4: DAMAGE | Z4: ACCURACY | AB4: DAMAGE | AC4: ACCURACY
C5: =IF(AND('ENTRY DATA'!D5=""),"",('ENTRY DATA'!D5)) | D5: =IF(AND('ENTRY DATA'!F5=""),"",('ENTRY DATA'!F5)) | E5: =IF(AND('ENTRY DATA'!B5=""),"",('ENTRY DATA'!B5)) -> 1 | L5: =COUNT(H5:J5) -> 0 | M5: =IF(AND(H5="",I5="",J5=""),"",(H5+I5+J5)) | P5: =C5 | Y5: =IF(AND(R5="",T5="",V5=""),"",SUM(R5,T5,V5)) | Z5: =IF(AND(S5="",U5="",W5=""),"",SUM(S5,U5,W5)) | AB5: =Y5/L5 -> #VALUE! | AC5: =Z5/L5 -> #VALUE!
C6: =IF(AND('ENTRY DATA'!D6=""),"",('ENTRY DATA'!D6)) | D6: =IF(AND('ENTRY DATA'!F6=""),"",('ENTRY DATA'!F6)) | E6: =IF(AND('ENTRY DATA'!B6=""),"",('ENTRY DATA'!B6)) | L6: =COUNT(H6:J6) -> 0 | M6: =IF(AND(H6="",I6="",J6=""),"",(H6+I6+J6)) | P6: =C6 | Y6: =IF(AND(R6="",T6="",V6=""),"",SUM(R6,T6,V6)) | Z6: =IF(AND(S6="",U6="",W6=""),"",SUM(S6,U6,W6)) | AB6: =Y6/L6 -> #VALUE! | AC6: =Z6/L6 -> #VALUE!
C7: =IF(AND('ENTRY DATA'!D7=""),"",('ENTRY DATA'!D7)) | D7: =IF(AND('ENTRY DATA'!F7=""),"",('ENTRY DATA'!F7)) | E7: =IF(AND('ENTRY DATA'!B7=""),"",('ENTRY DATA'!B7)) | L7: =COUNT(H7:J7) -> 0 | M7: =IF(AND(H7="",I7="",J7=""),"",(H7+I7+J7)) | P7: =C7 | Y7: =IF(AND(R7="",T7="",V7=""),"",SUM(R7,T7,V7)) | Z7: =IF(AND(S7="",U7="",W7=""),"",SUM(S7,U7,W7)) | AB7: =Y7/L7 -> #VALUE! | AC7: =Z7/L7 -> #VALUE!
C8: =IF(AND('ENTRY DATA'!D8=""),"",('ENTRY DATA'!D8)) | D8: =IF(AND('ENTRY DATA'!F8=""),"",('ENTRY DATA'!F8)) | E8: =IF(AND('ENTRY DATA'!B8=""),"",('ENTRY DATA'!B8)) | L8: =COUNT(H8:J8) -> 0 | M8: =IF(AND(H8="",I8="",J8=""),"",(H8+I8+J8)) | P8: =C8 | Y8: =IF(AND(R8="",T8="",V8=""),"",SUM(R8,T8,V8)) | Z8: =IF(AND(S8="",U8="",W8=""),"",SUM(S8,U8,W8)) | AB8: =Y8/L8 -> #VALUE! | AC8: =Z8/L8 -> #VALUE!
C9: =IF(AND('ENTRY DATA'!D9=""),"",('ENTRY DATA'!D9)) | D9: =IF(AND('ENTRY DATA'!F9=""),"",('ENTRY DATA'!F9)) | E9: =IF(AND('ENTRY DATA'!B9=""),"",('ENTRY DATA'!B9)) | L9: =COUNT(H9:J9) -> 0 | M9: =IF(AND(H9="",I9="",J9=""),"",(H9+I9+J9)) | P9: =C9 | Y9: =IF(AND(R9="",T9="",V9=""),"",SUM(R9,T9,V9)) | Z9: =IF(AND(S9="",U9="",W9=""),"",SUM(S9,U9,W9)) | AB9: =Y9/L9 -> #VALUE! | AC9: =Z9/L9 -> #VALUE!
C10: =IF(AND('ENTRY DATA'!D10=""),"",('ENTRY DATA'!D10)) | D10: =IF(AND('ENTRY DATA'!F10=""),"",('ENTRY DATA'!F10)) | E10: =IF(AND('ENTRY DATA'!B10=""),"",('ENTRY DATA'!B10)) | L10: =COUNT(H10:J10) -> 0 | M10: =IF(AND(H10="",I10="",J10=""),"",(H10+I10+J10)) | P10: =C10 | Y10: =IF(AND(R10="",T10="",V10=""),"",SUM(R10,T10,V10)) | Z10: =IF(AND(S10="",U10="",W10=""),"",SUM(S10,U10,W10)) | AB10: =Y10/L10 -> #VALUE! | AC10: =Z10/L10 -> #VALUE!
C11: =IF(AND('ENTRY DATA'!D11=""),"",('ENTRY DATA'!D11)) | D11: =IF(AND('ENTRY DATA'!F11=""),"",('ENTRY DATA'!F11)) | E11: =IF(AND('ENTRY DATA'!B11=""),"",('ENTRY DATA'!B11)) | L11: =COUNT(H11:J11) -> 0 | M11: =IF(AND(H11="",I11="",J11=""),"",(H11+I11+J11)) | P11: =C11 | Y11: =IF(AND(R11="",T11="",V11=""),"",SUM(R11,T11,V11)) | Z11: =IF(AND(S11="",U11="",W11=""),"",SUM(S11,U11,W11)) | AB11: =Y11/L11 -> #VALUE! | AC11: =Z11/L11 -> #VALUE!
C12: =IF(AND('ENTRY DATA'!D12=""),"",('ENTRY DATA'!D12)) | D12: =IF(AND('ENTRY DATA'!F12=""),"",('ENTRY DATA'!F12)) | E12: =IF(AND('ENTRY DATA'!B12=""),"",('ENTRY DATA'!B12)) | L12: =COUNT(H12:J12) -> 0 | M12: =IF(AND(H12="",I12="",J12=""),"",(H12+I12+J12)) | P12: =C12 | Y12: =IF(AND(R12="",T12="",V12=""),"",SUM(R12,T12,V12)) | Z12: =IF(AND(S12="",U12="",W12=""),"",SUM(S12,U12,W12)) | AB12: =Y12/L12 -> #VALUE! | AC12: =Z12/L12 -> #VALUE!
C13: =IF(AND('ENTRY DATA'!D13=""),"",('ENTRY DATA'!D13)) | D13: =IF(AND('ENTRY DATA'!F13=""),"",('ENTRY DATA'!F13)) | E13: =IF(AND('ENTRY DATA'!B13=""),"",('ENTRY DATA'!B13)) -> 2 | L13: =COUNT(H13:J13) -> 0 | M13: =IF(AND(H13="",I13="",J13=""),"",(H13+I13+J13)) | P13: =C13 | Y13: =IF(AND(R13="",T13="",V13=""),"",SUM(R13,T13,V13)) | Z13: =IF(AND(S13="",U13="",W13=""),"",SUM(S13,U13,W13)) | AB13: =Y13/L13 -> #VALUE! | AC13: =Z13/L13 -> #VALUE!
C14: =IF(AND('ENTRY DATA'!D14=""),"",('ENTRY DATA'!D14)) | D14: =IF(AND('ENTRY DATA'!F14=""),"",('ENTRY DATA'!F14)) | E14: =IF(AND('ENTRY DATA'!B14=""),"",('ENTRY DATA'!B14)) | L14: =COUNT(H14:J14) -> 0 | M14: =IF(AND(H14="",I14="",J14=""),"",(H14+I14+J14)) | P14: =C14 | Y14: =IF(AND(R14="",T14="",V14=""),"",SUM(R14,T14,V14)) | Z14: =IF(AND(S14="",U14="",W14=""),"",SUM(S14,U14,W14)) | AB14: =Y14/L14 -> #VALUE! | AC14: =Z14/L14 -> #VALUE!
C15: =IF(AND('ENTRY DATA'!D15=""),"",('ENTRY DATA'!D15)) | D15: =IF(AND('ENTRY DATA'!F15=""),"",('ENTRY DATA'!F15)) | E15: =IF(AND('ENTRY DATA'!B15=""),"",('ENTRY DATA'!B15)) | L15: =COUNT(H15:J15) -> 0 | M15: =IF(AND(H15="",I15="",J15=""),"",(H15+I15+J15)) | P15: =C15 | Y15: =IF(AND(R15="",T15="",V15=""),"",SUM(R15,T15,V15)) | Z15: =IF(AND(S15="",U15="",W15=""),"",SUM(S15,U15,W15)) | AB15: =Y15/L15 -> #VALUE! | AC15: =Z15/L15 -> #VALUE!
C16: =IF(AND('ENTRY DATA'!D16=""),"",('ENTRY DATA'!D16)) | D16: =IF(AND('ENTRY DATA'!F16=""),"",('ENTRY DATA'!F16)) | E16: =IF(AND('ENTRY DATA'!B16=""),"",('ENTRY DATA'!B16)) | L16: =COUNT(H16:J16) -> 0 | M16: =IF(AND(H16="",I16="",J16=""),"",(H16+I16+J16)) | P16: =C16 | Y16: =IF(AND(R16="",T16="",V16=""),"",SUM(R16,T16,V16)) | Z16: =IF(AND(S16="",U16="",W16=""),"",SUM(S16,U16,W16)) | AB16: =Y16/L16 -> #VALUE! | AC16: =Z16/L16 -> #VALUE!
... C300: =IF(AND('ENTRY DATA'!D300=""),"",('ENTRY DATA'!D300)) | D300: =IF(AND('ENTRY DATA'!F300=""),"",('ENTRY DATA'!F300)) | E300: =IF(AND('ENTRY DATA'!B300=""),"",('ENTRY DATA'!B300)) | L300: =COUNT(H300:J300) -> 0 | M300: =IF(AND(H300="",I300="",J300=""),"",(H300+I300+J300)) | P300: =C300 | Y300: =IF(AND(R300="",T300="",V300=""),"",SUM(R300,T300,V300)) | Z300: =IF(AND(S300="",U300="",W300=""),"",SUM(S300,U300,W300)) | AB300: =Y300/L300 -> #VALUE! | AC300: =Z300/L300 -> #VALUE!
P301: =C301 -> 0 | Y301: =IF(AND(R301="",T301="",V301=""),"",SUM(R301,T301,V301)) | Z301: =IF(AND(S301="",U301="",W301=""),"",SUM(S301,U301,W301)) | AB301: =Y301/L301 -> #VALUE! | AC301: =Z301/L301 -> #VALUE!
Y302: =IF(AND(R302="",T302="",V302=""),"",SUM(R302,T302,V302)) | Z302: =IF(AND(S302="",U302="",W302=""),"",SUM(S302,U302,W302))

Sheet DAY 3
R2: GAMES STATS II ( DAMAGES & ACCURACY )
H3: GAMES | L3: DAILY TOTAL | R3: LOBBY 1 | T3: LOBBY 2 | V3: LOBBY 3 | Y3: TOTAL | AB3: AVERAGE
C4: PLAYER NAME | D4: TEAM NAME | E4: SLOT | H4: LOBBY 1 | I4: LOBBY 2 | J4: LOBBY 3 | L4: MATCHES | M4: KILLS | P4: PLAYER NAME | R4: DAMAGE | S4: ACCURCY | T4: DAMAGE | U4: ACCURCY | V4: DAMAGE | W4: ACCURCY | Y4: DAMAGE | Z4: ACCURACY | AB4: DAMAGE | AC4: ACCURACY
C5: =IF(AND('ENTRY DATA'!D5=""),"",('ENTRY DATA'!D5)) | D5: =IF(AND('ENTRY DATA'!F5=""),"",('ENTRY DATA'!F5)) | E5: =IF(AND('ENTRY DATA'!B5=""),"",('ENTRY DATA'!B5)) -> 1 | L5: =COUNT(H5:J5) -> 0 | M5: =IF(AND(H5="",I5="",J5=""),"",(H5+I5+J5)) | P5: =C5 | Y5: =IF(AND(R5="",T5="",V5=""),"",SUM(R5,T5,V5)) | Z5: =IF(AND(S5="",U5="",W5=""),"",SUM(S5,U5,W5)) | AB5: =Y5/L5 -> #VALUE! | AC5: =Z5/L5 -> #VALUE!
C6: =IF(AND('ENTRY DATA'!D6=""),"",('ENTRY DATA'!D6)) | D6: =IF(AND('ENTRY DATA'!F6=""),"",('ENTRY DATA'!F6)) | E6: =IF(AND('ENTRY DATA'!B6=""),"",('ENTRY DATA'!B6)) | L6: =COUNT(H6:J6) -> 0 | M6: =IF(AND(H6="",I6="",J6=""),"",(H6+I6+J6)) | P6: =C6 | Y6: =IF(AND(R6="",T6="",V6=""),"",SUM(R6,T6,V6)) | Z6: =IF(AND(S6="",U6="",W6=""),"",SUM(S6,U6,W6)) | AB6: =Y6/L6 -> #VALUE! | AC6: =Z6/L6 -> #VALUE!
C7: =IF(AND('ENTRY DATA'!D7=""),"",('ENTRY DATA'!D7)) | D7: =IF(AND('ENTRY DATA'!F7=""),"",('ENTRY DATA'!F7)) | E7: =IF(AND('ENTRY DATA'!B7=""),"",('ENTRY DATA'!B7)) | L7: =COUNT(H7:J7) -> 0 | M7: =IF(AND(H7="",I7="",J7=""),"",(H7+I7+J7)) | P7: =C7 | Y7: =IF(AND(R7="",T7="",V7=""),"",SUM(R7,T7,V7)) | Z7: =IF(AND(S7="",U7="",W7=""),"",SUM(S7,U7,W7)) | AB7: =Y7/L7 -> #VALUE! | AC7: =Z7/L7 -> #VALUE!
C8: =IF(AND('ENTRY DATA'!D8=""),"",('ENTRY DATA'!D8)) | D8: =IF(AND('ENTRY DATA'!F8=""),"",('ENTRY DATA'!F8)) | E8: =IF(AND('ENTRY DATA'!B8=""),"",('ENTRY DATA'!B8)) | L8: =COUNT(H8:J8) -> 0 | M8: =IF(AND(H8="",I8="",J8=""),"",(H8+I8+J8)) | P8: =C8 | Y8: =IF(AND(R8="",T8="",V8=""),"",SUM(R8,T8,V8)) | Z8: =IF(AND(S8="",U8="",W8=""),"",SUM(S8,U8,W8)) | AB8: =Y8/L8 -> #VALUE! | AC8: =Z8/L8 -> #VALUE!
C9: =IF(AND('ENTRY DATA'!D9=""),"",('ENTRY DATA'!D9)) | D9: =IF(AND('ENTRY DATA'!F9=""),"",('ENTRY DATA'!F9)) | E9: =IF(AND('ENTRY DATA'!B9=""),"",('ENTRY DATA'!B9)) | L9: =COUNT(H9:J9) -> 0 | M9: =IF(AND(H9="",I9="",J9=""),"",(H9+I9+J9)) | P9: =C9 | Y9: =IF(AND(R9="",T9="",V9=""),"",SUM(R9,T9,V9)) | Z9: =IF(AND(S9="",U9="",W9=""),"",SUM(S9,U9,W9)) | AB9: =Y9/L9 -> #VALUE! | AC9: =Z9/L9 -> #VALUE!
C10: =IF(AND('ENTRY DATA'!D10=""),"",('ENTRY DATA'!D10)) | D10: =IF(AND('ENTRY DATA'!F10=""),"",('ENTRY DATA'!F10)) | E10: =IF(AND('ENTRY DATA'!B10=""),"",('ENTRY DATA'!B10)) | L10: =COUNT(H10:J10) -> 0 | M10: =IF(AND(H10="",I10="",J10=""),"",(H10+I10+J10)) | P10: =C10 | Y10: =IF(AND(R10="",T10="",V10=""),"",SUM(R10,T10,V10)) | Z10: =IF(AND(S10="",U10="",W10=""),"",SUM(S10,U10,W10)) | AB10: =Y10/L10 -> #VALUE! | AC10: =Z10/L10 -> #VALUE!
C11: =IF(AND('ENTRY DATA'!D11=""),"",('ENTRY DATA'!D11)) | D11: =IF(AND('ENTRY DATA'!F11=""),"",('ENTRY DATA'!F11)) | E11: =IF(AND('ENTRY DATA'!B11=""),"",('ENTRY DATA'!B11)) | L11: =COUNT(H11:J11) -> 0 | M11: =IF(AND(H11="",I11="",J11=""),"",(H11+I11+J11)) | P11: =C11 | Y11: =IF(AND(R11="",T11="",V11=""),"",SUM(R11,T11,V11)) | Z11: =IF(AND(S11="",U11="",W11=""),"",SUM(S11,U11,W11)) | AB11: =Y11/L11 -> #VALUE! | AC11: =Z11/L11 -> #VALUE!
C12: =IF(AND('ENTRY DATA'!D12=""),"",('ENTRY DATA'!D12)) | D12: =IF(AND('ENTRY DATA'!F12=""),"",('ENTRY DATA'!F12)) | E12: =IF(AND('ENTRY DATA'!B12=""),"",('ENTRY DATA'!B12)) | L12: =COUNT(H12:J12) -> 0 | M12: =IF(AND(H12="",I12="",J12=""),"",(H12+I12+J12)) | P12: =C12 | Y12: =IF(AND(R12="",T12="",V12=""),"",SUM(R12,T12,V12)) | Z12: =IF(AND(S12="",U12="",W12=""),"",SUM(S12,U12,W12)) | AB12: =Y12/L12 -> #VALUE! | AC12: =Z12/L12 -> #VALUE!
C13: =IF(AND('ENTRY DATA'!D13=""),"",('ENTRY DATA'!D13)) | D13: =IF(AND('ENTRY DATA'!F13=""),"",('ENTRY DATA'!F13)) | E13: =IF(AND('ENTRY DATA'!B13=""),"",('ENTRY DATA'!B13)) -> 2 | L13: =COUNT(H13:J13) -> 0 | M13: =IF(AND(H13="",I13="",J13=""),"",(H13+I13+J13)) | P13: =C13 | Y13: =IF(AND(R13="",T13="",V13=""),"",SUM(R13,T13,V13)) | Z13: =IF(AND(S13="",U13="",W13=""),"",SUM(S13,U13,W13)) | AB13: =Y13/L13 -> #VALUE! | AC13: =Z13/L13 -> #VALUE!
C14: =IF(AND('ENTRY DATA'!D14=""),"",('ENTRY DATA'!D14)) | D14: =IF(AND('ENTRY DATA'!F14=""),"",('ENTRY DATA'!F14)) | E14: =IF(AND('ENTRY DATA'!B14=""),"",('ENTRY DATA'!B14)) | L14: =COUNT(H14:J14) -> 0 | M14: =IF(AND(H14="",I14="",J14=""),"",(H14+I14+J14)) | P14: =C14 | Y14: =IF(AND(R14="",T14="",V14=""),"",SUM(R14,T14,V14)) | Z14: =IF(AND(S14="",U14="",W14=""),"",SUM(S14,U14,W14)) | AB14: =Y14/L14 -> #VALUE! | AC14: =Z14/L14 -> #VALUE!
C15: =IF(AND('ENTRY DATA'!D15=""),"",('ENTRY DATA'!D15)) | D15: =IF(AND('ENTRY DATA'!F15=""),"",('ENTRY DATA'!F15)) | E15: =IF(AND('ENTRY DATA'!B15=""),"",('ENTRY DATA'!B15)) | L15: =COUNT(H15:J15) -> 0 | M15: =IF(AND(H15="",I15="",J15=""),"",(H15+I15+J15)) | P15: =C15 | Y15: =IF(AND(R15="",T15="",V15=""),"",SUM(R15,T15,V15)) | Z15: =IF(AND(S15="",U15="",W15=""),"",SUM(S15,U15,W15)) | AB15: =Y15/L15 -> #VALUE! | AC15: =Z15/L15 -> #VALUE!
C16: =IF(AND('ENTRY DATA'!D16=""),"",('ENTRY DATA'!D16)) | D16: =IF(AND('ENTRY DATA'!F16=""),"",('ENTRY DATA'!F16)) | E16: =IF(AND('ENTRY DATA'!B16=""),"",('ENTRY DATA'!B16)) | L16: =COUNT(H16:J16) -> 0 | M16: =IF(AND(H16="",I16="",J16=""),"",(H16+I16+J16)) | P16: =C16 | Y16: =IF(AND(R16="",T16="",V16=""),"",SUM(R16,T16,V16)) | Z16: =IF(AND(S16="",U16="",W16=""),"",SUM(S16,U16,W16)) | AB16: =Y16/L16 -> #VALUE! | AC16: =Z16/L16 -> #VALUE!
... C300: =IF(AND('ENTRY DATA'!D300=""),"",('ENTRY DATA'!D300)) | D300: =IF(AND('ENTRY DATA'!F300=""),"",('ENTRY DATA'!F300)) | E300: =IF(AND('ENTRY DATA'!B300=""),"",('ENTRY DATA'!B300)) | L300: =COUNT(H300:J300) -> 0 | M300: =IF(AND(H300="",I300="",J300=""),"",(H300+I300+J300)) | P300: =C300 | Y300: =IF(AND(R300="",T300="",V300=""),"",SUM(R300,T300,V300)) | Z300: =IF(AND(S300="",U300="",W300=""),"",SUM(S300,U300,W300)) | AB300: =Y300/L300 -> #VALUE! | AC300: =Z300/L300 -> #VALUE!
P301: =C301 -> 0 | Y301: =IF(AND(R301="",T301="",V301=""),"",SUM(R301,T301,V301)) | Z301: =IF(AND(S301="",U301="",W301=""),"",SUM(S301,U301,W301)) | AB301: =Y301/L301 -> #VALUE! | AC301: =Z301/L301 -> #VALUE!
Y302: =IF(AND(R302="",T302="",V302=""),"",SUM(R302,T302,V302)) | Z302: =IF(AND(S302="",U302="",W302=""),"",SUM(S302,U302,W302))

Sheet DAY 4
R2: GAMES STATS II ( DAMAGES & ACCURACY )
H3: GAMES | L3: DAILY TOTAL | R3: LOBBY 1 | T3: LOBBY 2 | V3: LOBBY 3 | Y3: TOTAL | AB3: AVERAGE
C4: PLAYER NAME | D4: TEAM NAME | E4: SLOT | H4: LOBBY 1 | I4: LOBBY 2 | J4: LOBBY 3 | L4: MATCHES | M4: KILLS | P4: PLAYER NAME | R4: DAMAGE | S4: ACCURCY | T4: DAMAGE | U4: ACCURCY | V4: DAMAGE | W4: ACCURCY | Y4: DAMAGE | Z4: ACCURACY | AB4: DAMAGE | AC4: ACCURACY
C5: =IF(AND('ENTRY DATA'!D5=""),"",('ENTRY DATA'!D5)) | D5: =IF(AND('ENTRY DATA'!F5=""),"",('ENTRY DATA'!F5)) | E5: =IF(AND('ENTRY DATA'!B5=""),"",('ENTRY DATA'!B5)) -> 1 | L5: =COUNT(H5:J5) -> 0 | M5: =IF(AND(H5="",I5="",J5=""),"",(H5+I5+J5)) | P5: =C5 | Y5: =IF(AND(R5="",T5="",V5=""),"",SUM(R5,T5,V5)) | Z5: =IF(AND(S5="",U5="",W5=""),"",SUM(S5,U5,W5)) | AB5: =Y5/L5 -> #VALUE! | AC5: =Z5/L5 -> #VALUE!
C6: =IF(AND('ENTRY DATA'!D6=""),"",('ENTRY DATA'!D6)) | D6: =IF(AND('ENTRY DATA'!F6=""),"",('ENTRY DATA'!F6)) | E6: =IF(AND('ENTRY DATA'!B6=""),"",('ENTRY DATA'!B6)) | L6: =COUNT(H6:J6) -> 0 | M6: =IF(AND(H6="",I6="",J6=""),"",(H6+I6+J6)) | P6: =C6 | Y6: =IF(AND(R6="",T6="",V6=""),"",SUM(R6,T6,V6)) | Z6: =IF(AND(S6="",U6="",W6=""),"",SUM(S6,U6,W6)) | AB6: =Y6/L6 -> #VALUE! | AC6: =Z6/L6 -> #VALUE!
C7: =IF(AND('ENTRY DATA'!D7=""),"",('ENTRY DATA'!D7)) | D7: =IF(AND('ENTRY DATA'!F7=""),"",('ENTRY DATA'!F7)) | E7: =IF(AND('ENTRY DATA'!B7=""),"",('ENTRY DATA'!B7)) | L7: =COUNT(H7:J7) -> 0 | M7: =IF(AND(H7="",I7="",J7=""),"",(H7+I7+J7)) | P7: =C7 | Y7: =IF(AND(R7="",T7="",V7=""),"",SUM(R7,T7,V7)) | Z7: =IF(AND(S7="",U7="",W7=""),"",SUM(S7,U7,W7)) | AB7: =Y7/L7 -> #VALUE! | AC7: =Z7/L7 -> #VALUE!
C8: =IF(AND('ENTRY DATA'!D8=""),"",('ENTRY DATA'!D8)) | D8: =IF(AND('ENTRY DATA'!F8=""),"",('ENTRY DATA'!F8)) | E8: =IF(AND('ENTRY DATA'!B8=""),"",('ENTRY DATA'!B8)) | L8: =COUNT(H8:J8) -> 0 | M8: =IF(AND(H8="",I8="",J8=""),"",(H8+I8+J8)) | P8: =C8 | Y8: =IF(AND(R8="",T8="",V8=""),"",SUM(R8,T8,V8)) | Z8: =IF(AND(S8="",U8="",W8=""),"",SUM(S8,U8,W8)) | AB8: =Y8/L8 -> #VALUE! | AC8: =Z8/L8 -> #VALUE!
C9: =IF(AND('ENTRY DATA'!D9=""),"",('ENTRY DATA'!D9)) | D9: =IF(AND('ENTRY DATA'!F9=""),"",('ENTRY DATA'!F9)) | E9: =IF(AND('ENTRY DATA'!B9=""),"",('ENTRY DATA'!B9)) | L9: =COUNT(H9:J9) -> 0 | M9: =IF(AND(H9="",I9="",J9=""),"",(H9+I9+J9)) | P9: =C9 | Y9: =IF(AND(R9="",T9="",V9=""),"",SUM(R9,T9,V9)) | Z9: =IF(AND(S9="",U9="",W9=""),"",SUM(S9,U9,W9)) | AB9: =Y9/L9 -> #VALUE! | AC9: =Z9/L9 -> #VALUE!
C10: =IF(AND('ENTRY DATA'!D10=""),"",('ENTRY DATA'!D10)) | D10: =IF(AND('ENTRY DATA'!F10=""),"",('ENTRY DATA'!F10)) | E10: =IF(AND('ENTRY DATA'!B10=""),"",('ENTRY DATA'!B10)) | L10: =COUNT(H10:J10) -> 0 | M10: =IF(AND(H10="",I10="",J10=""),"",(H10+I10+J10)) | P10: =C10 | Y10: =IF(AND(R10="",T10="",V10=""),"",SUM(R10,T10,V10)) | Z10: =IF(AND(S10="",U10="",W10=""),"",SUM(S10,U10,W10)) | AB10: =Y10/L10 -> #VALUE! | AC10: =Z10/L10 -> #VALUE!
C11: =IF(AND('ENTRY DATA'!D11=""),"",('ENTRY DATA'!D11)) | D11: =IF(AND('ENTRY DATA'!F11=""),"",('ENTRY DATA'!F11)) | E11: =IF(AND('ENTRY DATA'!B11=""),"",('ENTRY DATA'!B11)) | L11: =COUNT(H11:J11) -> 0 | M11: =IF(AND(H11="",I11="",J11=""),"",(H11+I11+J11)) | P11: =C11 | Y11: =IF(AND(R11="",T11="",V11=""),"",SUM(R11,T11,V11)) | Z11: =IF(AND(S11="",U11="",W11=""),"",SUM(S11,U11,W11)) | AB11: =Y11/L11 -> #VALUE! | AC11: =Z11/L11 -> #VALUE!
C12: =IF(AND('ENTRY DATA'!D12=""),"",('ENTRY DATA'!D12)) | D12: =IF(AND('ENTRY DATA'!F12=""),"",('ENTRY DATA'!F12)) | E12: =IF(AND('ENTRY DATA'!B12=""),"",('ENTRY DATA'!B12)) | L12: =COUNT(H12:J12) -> 0 | M12: =IF(AND(H12="",I12="",J12=""),"",(H12+I12+J12)) | P12: =C12 | Y12: =IF(AND(R12="",T12="",V12=""),"",SUM(R12,T12,V12)) | Z12: =IF(AND(S12="",U12="",W12=""),"",SUM(S12,U12,W12)) | AB12: =Y12/L12 -> #VALUE! | AC12: =Z12/L12 -> #VALUE!
C13: =IF(AND('ENTRY DATA'!D13=""),"",('ENTRY DATA'!D13)) | D13: =IF(AND('ENTRY DATA'!F13=""),"",('ENTRY DATA'!F13)) | E13: =IF(AND('ENTRY DATA'!B13=""),"",('ENTRY DATA'!B13)) -> 2 | L13: =COUNT(H13:J13) -> 0 | M13: =IF(AND(H13="",I13="",J13=""),"",(H13+I13+J13)) | P13: =C13 | Y13: =IF(AND(R13="",T13="",V13=""),"",SUM(R13,T13,V13)) | Z13: =IF(AND(S13="",U13="",W13=""),"",SUM(S13,U13,W13)) | AB13: =Y13/L13 -> #VALUE! | AC13: =Z13/L13 -> #VALUE!
C14: =IF(AND('ENTRY DATA'!D14=""),"",('ENTRY DATA'!D14)) | D14: =IF(AND('ENTRY DATA'!F14=""),"",('ENTRY DATA'!F14)) | E14: =IF(AND('ENTRY DATA'!B14=""),"",('ENTRY DATA'!B14)) | L14: =COUNT(H14:J14) -> 0 | M14: =IF(AND(H14="",I14="",J14=""),"",(H14+I14+J14)) | P14: =C14 | Y14: =IF(AND(R14="",T14="",V14=""),"",SUM(R14,T14,V14)) | Z14: =IF(AND(S14="",U14="",W14=""),"",SUM(S14,U14,W14)) | AB14: =Y14/L14 -> #VALUE! | AC14: =Z14/L14 -> #VALUE!
C15: =IF(AND('ENTRY DATA'!D15=""),"",('ENTRY DATA'!D15)) | D15: =IF(AND('ENTRY DATA'!F15=""),"",('ENTRY DATA'!F15)) | E15: =IF(AND('ENTRY DATA'!B15=""),"",('ENTRY DATA'!B15)) | L15: =COUNT(H15:J15) -> 0 | M15: =IF(AND(H15="",I15="",J15=""),"",(H15+I15+J15)) | P15: =C15 | Y15: =IF(AND(R15="",T15="",V15=""),"",SUM(R15,T15,V15)) | Z15: =IF(AND(S15="",U15="",W15=""),"",SUM(S15,U15,W15)) | AB15: =Y15/L15 -> #VALUE! | AC15: =Z15/L15 -> #VALUE!
C16: =IF(AND('ENTRY DATA'!D16=""),"",('ENTRY DATA'!D16)) | D16: =IF(AND('ENTRY DATA'!F16=""),"",('ENTRY DATA'!F16)) | E16: =IF(AND('ENTRY DATA'!B16=""),"",('ENTRY DATA'!B16)) | L16: =COUNT(H16:J16) -> 0 | M16: =IF(AND(H16="",I16="",J16=""),"",(H16+I16+J16)) | P16: =C16 | Y16: =IF(AND(R16="",T16="",V16=""),"",SUM(R16,T16,V16)) | Z16: =IF(AND(S16="",U16="",W16=""),"",SUM(S16,U16,W16)) | AB16: =Y16/L16 -> #VALUE! | AC16: =Z16/L16 -> #VALUE!
... C300: =IF(AND('ENTRY DATA'!D300=""),"",('ENTRY DATA'!D300)) | D300: =IF(AND('ENTRY DATA'!F300=""),"",('ENTRY DATA'!F300)) | E300: =IF(AND('ENTRY DATA'!B300=""),"",('ENTRY DATA'!B300)) | L300: =COUNT(H300:J300) -> 0 | M300: =IF(AND(H300="",I300="",J300=""),"",(H300+I300+J300)) | P300: =C300 | Y300: =IF(AND(R300="",T300="",V300=""),"",SUM(R300,T300,V300)) | Z300: =IF(AND(S300="",U300="",W300=""),"",SUM(S300,U300,W300)) | AB300: =Y300/L300 -> #VALUE! | AC300: =Z300/L300 -> #VALUE!
P301: =C301 -> 0 | Y301: =IF(AND(R301="",T301="",V301=""),"",SUM(R301,T301,V301)) | Z301: =IF(AND(S301="",U301="",W301=""),"",SUM(S301,U301,W301)) | AB301: =Y301/L301 -> #VALUE! | AC301: =Z301/L301 -> #VALUE!
Y302: =IF(AND(R302="",T302="",V302=""),"",SUM(R302,T302,V302)) | Z302: =IF(AND(S302="",U302="",W302=""),"",SUM(S302,U302,W302))

Sheet DAY 5
R2: GAMES STATS II ( DAMAGES & ACCURACY )
H3: GAMES | L3: DAILY TOTAL | R3: LOBBY 1 | T3: LOBBY 2 | V3: LOBBY 3 | Y3: TOTAL | AB3: AVERAGE
C4: PLAYER NAME | D4: TEAM NAME | E4: SLOT | H4: LOBBY 1 | I4: LOBBY 2 | J4: LOBBY 3 | L4: MATCHES | M4: KILLS | P4: PLAYER NAME | R4: DAMAGE | S4: ACCURCY | T4: DAMAGE | U4: ACCURCY | V4: DAMAGE | W4: ACCURCY | Y4: DAMAGE | Z4: ACCURACY | AB4: DAMAGE | AC4: ACCURACY
C5: =IF(AND('ENTRY DATA'!D5=""),"",('ENTRY DATA'!D5)) | D5: =IF(AND('ENTRY DATA'!F5=""),"",('ENTRY DATA'!F5)) | E5: =IF(AND('ENTRY DATA'!B5=""),"",('ENTRY DATA'!B5)) -> 1 | L5: =COUNT(H5:J5) -> 0 | M5: =IF(AND(H5="",I5="",J5=""),"",(H5+I5+J5)) | P5: =C5 | Y5: =IF(AND(R5="",T5="",V5=""),"",SUM(R5,T5,V5)) | Z5: =IF(AND(S5="",U5="",W5=""),"",SUM(S5,U5,W5)) | AB5: =Y5/L5 -> #VALUE! | AC5: =Z5/L5 -> #VALUE!
C6: =IF(AND('ENTRY DATA'!D6=""),"",('ENTRY DATA'!D6)) | D6: =IF(AND('ENTRY DATA'!F6=""),"",('ENTRY DATA'!F6)) | E6: =IF(AND('ENTRY DATA'!B6=""),"",('ENTRY DATA'!B6)) | L6: =COUNT(H6:J6) -> 0 | M6: =IF(AND(H6="",I6="",J6=""),"",(H6+I6+J6)) | P6: =C6 | Y6: =IF(AND(R6="",T6="",V6=""),"",SUM(R6,T6,V6)) | Z6: =IF(AND(S6="",U6="",W6=""),"",SUM(S6,U6,W6)) | AB6: =Y6/L6 -> #VALUE! | AC6: =Z6/L6 -> #VALUE!
C7: =IF(AND('ENTRY DATA'!D7=""),"",('ENTRY DATA'!D7)) | D7: =IF(AND('ENTRY DATA'!F7=""),"",('ENTRY DATA'!F7)) | E7: =IF(AND('ENTRY DATA'!B7=""),"",('ENTRY DATA'!B7)) | L7: =COUNT(H7:J7) -> 0 | M7: =IF(AND(H7="",I7="",J7=""),"",(H7+I7+J7)) | P7: =C7 | Y7: =IF(AND(R7="",T7="",V7=""),"",SUM(R7,T7,V7)) | Z7: =IF(AND(S7="",U7="",W7=""),"",SUM(S7,U7,W7)) | AB7: =Y7/L7 -> #VALUE! | AC7: =Z7/L7 -> #VALUE!
C8: =IF(AND('ENTRY DATA'!D8=""),"",('ENTRY DATA'!D8)) | D8: =IF(AND('ENTRY DATA'!F8=""),"",('ENTRY DATA'!F8)) | E8: =IF(AND('ENTRY DATA'!B8=""),"",('ENTRY DATA'!B8)) | L8: =COUNT(H8:J8) -> 0 | M8: =IF(AND(H8="",I8="",J8=""),"",(H8+I8+J8)) | P8: =C8 | Y8: =IF(AND(R8="",T8="",V8=""),"",SUM(R8,T8,V8)) | Z8: =IF(AND(S8="",U8="",W8=""),"",SUM(S8,U8,W8)) | AB8: =Y8/L8 -> #VALUE! | AC8: =Z8/L8 -> #VALUE!
C9: =IF(AND('ENTRY DATA'!D9=""),"",('ENTRY DATA'!D9)) | D9: =IF(AND('ENTRY DATA'!F9=""),"",('ENTRY DATA'!F9)) | E9: =IF(AND('ENTRY DATA'!B9=""),"",('ENTRY DATA'!B9)) | L9: =COUNT(H9:J9) -> 0 | M9: =IF(AND(H9="",I9="",J9=""),"",(H9+I9+J9)) | P9: =C9 | Y9: =IF(AND(R9="",T9="",V9=""),"",SUM(R9,T9,V9)) | Z9: =IF(AND(S9="",U9="",W9=""),"",SUM(S9,U9,W9)) | AB9: =Y9/L9 -> #VALUE! | AC9: =Z9/L9 -> #VALUE!
C10: =IF(AND('ENTRY DATA'!D10=""),"",('ENTRY DATA'!D10)) | D10: =IF(AND('ENTRY DATA'!F10=""),"",('ENTRY DATA'!F10)) | E10: =IF(AND('ENTRY DATA'!B10=""),"",('ENTRY DATA'!B10)) | L10: =COUNT(H10:J10) -> 0 | M10: =IF(AND(H10="",I10="",J10=""),"",(H10+I10+J10)) | P10: =C10 | Y10: =IF(AND(R10="",T10="",V10=""),"",SUM(R10,T10,V10)) | Z10: =IF(AND(S10="",U10="",W10=""),"",SUM(S10,U10,W10)) | AB10: =Y10/L10 -> #VALUE! | AC10: =Z10/L10 -> #VALUE!
C11: =IF(AND('ENTRY DATA'!D11=""),"",('ENTRY DATA'!D11)) | D11: =IF(AND('ENTRY DATA'!F11=""),"",('ENTRY DATA'!F11)) | E11: =IF(AND('ENTRY DATA'!B11=""),"",('ENTRY DATA'!B11)) | L11: =COUNT(H11:J11) -> 0 | M11: =IF(AND(H11="",I11="",J11=""),"",(H11+I11+J11)) | P11: =C11 | Y11: =IF(AND(R11="",T11="",V11=""),"",SUM(R11,T11,V11)) | Z11: =IF(AND(S11="",U11="",W11=""),"",SUM(S11,U11,W11)) | AB11: =Y11/L11 -> #VALUE! | AC11: =Z11/L11 -> #VALUE!
C12: =IF(AND('ENTRY DATA'!D12=""),"",('ENTRY DATA'!D12)) | D12: =IF(AND('ENTRY DATA'!F12=""),"",('ENTRY DATA'!F12)) | E12: =IF(AND('ENTRY DATA'!B12=""),"",('ENTRY DATA'!B12)) | L12: =COUNT(H12:J12) -> 0 | M12: =IF(AND(H12="",I12="",J12=""),"",(H12+I12+J12)) | P12: =C12 | Y12: =IF(AND(R12="",T12="",V12=""),"",SUM(R12,T12,V12)) | Z12: =IF(AND(S12="",U12="",W12=""),"",SUM(S12,U12,W12)) | AB12: =Y12/L12 -> #VALUE! | AC12: =Z12/L12 -> #VALUE!
C13: =IF(AND('ENTRY DATA'!D13=""),"",('ENTRY DATA'!D13)) | D13: =IF(AND('ENTRY DATA'!F13=""),"",('ENTRY DATA'!F13)) | E13: =IF(AND('ENTRY DATA'!B13=""),"",('ENTRY DATA'!B13)) -> 2 | L13: =COUNT(H13:J13) -> 0 | M13: =IF(AND(H13="",I13="",J13=""),"",(H13+I13+J13)) | P13: =C13 | Y13: =IF(AND(R13="",T13="",V13=""),"",SUM(R13,T13,V13)) | Z13: =IF(AND(S13="",U13="",W13=""),"",SUM(S13,U13,W13)) | AB13: =Y13/L13 -> #VALUE! | AC13: =Z13/L13 -> #VALUE!
C14: =IF(AND('ENTRY DATA'!D14=""),"",('ENTRY DATA'!D14)) | D14: =IF(AND('ENTRY DATA'!F14=""),"",('ENTRY DATA'!F14)) | E14: =IF(AND('ENTRY DATA'!B14=""),"",('ENTRY DATA'!B14)) | L14: =COUNT(H14:J14) -> 0 | M14: =IF(AND(H14="",I14="",J14=""),"",(H14+I14+J14)) | P14: =C14 | Y14: =IF(AND(R14="",T14="",V14=""),"",SUM(R14,T14,V14)) | Z14: =IF(AND(S14="",U14="",W14=""),"",SUM(S14,U14,W14)) | AB14: =Y14/L14 -> #VALUE! | AC14: =Z14/L14 -> #VALUE!
C15: =IF(AND('ENTRY DATA'!D15=""),"",('ENTRY DATA'!D15)) | D15: =IF(AND('ENTRY DATA'!F15=""),"",('ENTRY DATA'!F15)) | E15: =IF(AND('ENTRY DATA'!B15=""),"",('ENTRY DATA'!B15)) | L15: =COUNT(H15:J15) -> 0 | M15: =IF(AND(H15="",I15="",J15=""),"",(H15+I15+J15)) | P15: =C15 | Y15: =IF(AND(R15="",T15="",V15=""),"",SUM(R15,T15,V15)) | Z15: =IF(AND(S15="",U15="",W15=""),"",SUM(S15,U15,W15)) | AB15: =Y15/L15 -> #VALUE! | AC15: =Z15/L15 -> #VALUE!
C16: =IF(AND('ENTRY DATA'!D16=""),"",('ENTRY DATA'!D16)) | D16: =IF(AND('ENTRY DATA'!F16=""),"",('ENTRY DATA'!F16)) | E16: =IF(AND('ENTRY DATA'!B16=""),"",('ENTRY DATA'!B16)) | L16: =COUNT(H16:J16) -> 0 | M16: =IF(AND(H16="",I16="",J16=""),"",(H16+I16+J16)) | P16: =C16 | Y16: =IF(AND(R16="",T16="",V16=""),"",SUM(R16,T16,V16)) | Z16: =IF(AND(S16="",U16="",W16=""),"",SUM(S16,U16,W16)) | AB16: =Y16/L16 -> #VALUE! | AC16: =Z16/L16 -> #VALUE!
... C300: =IF(AND('ENTRY DATA'!D300=""),"",('ENTRY DATA'!D300)) | D300: =IF(AND('ENTRY DATA'!F300=""),"",('ENTRY DATA'!F300)) | E300: =IF(AND('ENTRY DATA'!B300=""),"",('ENTRY DATA'!B300)) | L300: =COUNT(H300:J300) -> 0 | M300: =IF(AND(H300="",I300="",J300=""),"",(H300+I300+J300)) | P300: =C300 | Y300: =IF(AND(R300="",T300="",V300=""),"",SUM(R300,T300,V300)) | Z300: =IF(AND(S300="",U300="",W300=""),"",SUM(S300,U300,W300)) | AB300: =Y300/L300 -> #VALUE! | AC300: =Z300/L300 -> #VALUE!
P301: =C301 -> 0 | Y301: =IF(AND(R301="",T301="",V301=""),"",SUM(R301,T301,V301)) | Z301: =IF(AND(S301="",U301="",W301=""),"",SUM(S301,U301,W301)) | AB301: =Y301/L301 -> #VALUE! | AC301: =Z301/L301 -> #VALUE!
Y302: =IF(AND(R302="",T302="",V302=""),"",SUM(R302,T302,V302)) | Z302: =IF(AND(S302="",U302="",W302=""),"",SUM(S302,U302,W302))

Sheet ROSTER UPDATE
AB2: GAMES STATS II ( DAMAGES & ACCURACY )
H3: RU DAY 1(DAY 3) | K3: RU DAY 2(DAY 4) | N3: RU DAY 3( DAY 5) | R3: KILL TABLE DATA | V3: EVENTS CALCULATOR | AB3: LOBBY 1 | AD3: LOBBY 2 | AF3: LOBBY 3 | AI3: TOTAL | AL3: AVERAGE
B4: PRO NAME | C4: CLAN | E4: PLAYER NAME | F4: TEAM NAME | H4: L1 | I4: L2 | J4: L3 | K4: L1 | L4: L2 | M4: L3 | N4: L1 | O4: L2 | P4: L3 | R4: MATCHES | S4: EVENTS | T4: KILLS | V4: EVENTS 1 | W4: EVENTS 2 | X4: EVENTS 3 | Z4: PLAYER NAME | AB4: DAMAGE | AC4: ACCURCY | AD4: DAMAGE | AE4: ACCURCY | AF4: DAMAGE | AG4: ACCURCY | AI4: DAMAGE | AJ4: ACCURACY | AL4: DAMAGE | AM4: ACCURACY
H5: 3 | I5: 6 | J5: 10 | R5: =COUNT(H5:P5) -> 3 | S5: =SUM(V5:X5) -> 1 | T5: =IF(AND(H5="",I5="",J5="",K5="",L5="",M5="",N5="",O5="",P5=""),"",(H5+I5+J5+K5+L5+M5+N5+O5+P5)) -> 19 | V5: =IF(COUNTA(H5:J5)>0,1,"") -> 1 | W5: =IF(COUNTA(K5:M5)>0,1,"") | X5: =IF(COUNTA(N5:P5)>0,1,"") | Z5: =E5 -> 0 | AI5: =IF(AND(AB5="",AD5="",AF5=""),"",SUM(AB5,AD5,AF5)) | AJ5: =IF(AND(AC5="",AE5="",AG5=""),"",SUM(AC5,AE5,AG5)) | AL5: =AI5/R5 -> #VALUE! | AM5: =AJ5/R5 -> #VALUE!
R6: =COUNT(H6:P6) -> 0 | S6: =SUM(V6:X6) -> 0 | T6: =IF(AND(H6="",I6="",J6="",K6="",L6="",M6="",N6="",O6="",P6=""),"",(H6+I6+J6+K6+L6+M6+N6+O6+P6)) | V6: =IF(COUNTA(H6:J6)>0,1,"") | W6: =IF(COUNTA(K6:M6)>0,1,"") | X6: =IF(COUNTA(N6:P6)>0,1,"") | Z6: =E6 -> 0 | AI6: =IF(AND(AB6="",AD6="",AF6=""),"",SUM(AB6,AD6,AF6)) | AJ6: =IF(AND(AC6="",AE6="",AG6=""),"",SUM(AC6,AE6,AG6)) | AL6: =AI6/R6 -> #VALUE! | AM6: =AJ6/R6 -> #VALUE!
R7: =COUNT(H7:P7) -> 0 | S7: =SUM(V7:X7) -> 0 | T7: =IF(AND(H7="",I7="",J7="",K7="",L7="",M7="",N7="",O7="",P7=""),"",(H7+I7+J7+K7+L7+M7+N7+O7+P7)) | V7: =IF(COUNTA(H7:J7)>0,1,"") | W7: =IF(COUNTA(K7:M7)>0,1,"") | X7: =IF(COUNTA(N7:P7)>0,1,"") | Z7: =E7 -> 0 | AI7: =IF(AND(AB7="",AD7="",AF7=""),"",SUM(AB7,AD7,AF7)) | AJ7: =IF(AND(AC7="",AE7="",AG7=""),"",SUM(AC7,AE7,AG7)) | AL7: =AI7/R7 -> #VALUE! | AM7: =AJ7/R7 -> #VALUE!
R8: =COUNT(H8:P8) -> 0 | S8: =SUM(V8:X8) -> 0 | T8: =IF(AND(H8="",I8="",J8="",K8="",L8="",M8="",N8="",O8="",P8=""),"",(H8+I8+J8+K8+L8+M8+N8+O8+P8)) | V8: =IF(COUNTA(H8:J8)>0,1,"") | W8: =IF(COUNTA(K8:M8)>0,1,"") | X8: =IF(COUNTA(N8:P8)>0,1,"") | Z8: =E8 -> 0 | AI8: =IF(AND(AB8="",AD8="",AF8=""),"",SUM(AB8,AD8,AF8)) | AJ8: =IF(AND(AC8="",AE8="",AG8=""),"",SUM(AC8,AE8,AG8)) | AL8: =AI8/R8 -> #VALUE! | AM8: =AJ8/R8 -> #VALUE!
R9: =COUNT(H9:P9) -> 0 | S9: =SUM(V9:X9) -> 0 | T9: =IF(AND(H9="",I9="",J9="",K9="",L9="",M9="",N9="",O9="",P9=""),"",(H9+I9+J9+K9+L9+M9+N9+O9+P9)) | V9: =IF(COUNTA(H9:J9)>0,1,"") | W9: =IF(COUNTA(K9:M9)>0,1,"") | X9: =IF(COUNTA(N9:P9)>0,1,"") | Z9: =E9 -> 0 | AI9: =IF(AND(AB9="",AD9="",AF9=""),"",SUM(AB9,AD9,AF9)) | AJ9: =IF(AND(AC9="",AE9="",AG9=""),"",SUM(AC9,AE9,AG9)) | AL9: =AI9/R9 -> #VALUE! | AM9: =AJ9/R9 -> #VALUE!
R10: =COUNT(H10:P10) -> 0 | S10: =SUM(V10:X10) -> 0 | T10: =IF(AND(H10="",I10="",J10="",K10="",L10="",M10="",N10="",O10="",P10=""),"",(H10+I10+J10+K10+L10+M10+N10+O10+P10)) | V10: =IF(COUNTA(H10:J10)>0,1,"") | W10: =IF(COUNTA(K10:M10)>0,1,"") | X10: =IF(COUNTA(N10:P10)>0,1,"") | Z10: =E10 -> 0 | AI10: =IF(AND(AB10="",AD10="",AF10=""),"",SUM(AB10,AD10,AF10)) | AJ10: =IF(AND(AC10="",AE10="",AG10=""),"",SUM(AC10,AE10,AG10)) | AL10: =AI10/R10 -> #VALUE! | AM10: =AJ10/R10 -> #VALUE!
R11: =COUNT(H11:P11) -> 0 | S11: =SUM(V11:X11) -> 0 | T11: =IF(AND(H11="",I11="",J11="",K11="",L11="",M11="",N11="",O11="",P11=""),"",(H11+I11+J11+K11+L11+M11+N11+O11+P11)) | V11: =IF(COUNTA(H11:J11)>0,1,"") | W11: =IF(COUNTA(K11:M11)>0,1,"") | X11: =IF(COUNTA(N11:P11)>0,1,"") | Z11: =E11 -> 0 | AI11: =IF(AND(AB11="",AD11="",AF11=""),"",SUM(AB11,AD11,AF11)) | AJ11: =IF(AND(AC11="",AE11="",AG11=""),"",SUM(AC11,AE11,AG11)) | AL11: =AI11/R11 -> #VALUE! | AM11: =AJ11/R11 -> #VALUE!
R12: =COUNT(H12:P12) -> 0 | S12: =SUM(V12:X12) -> 0 | T12: =IF(AND(H12="",I12="",J12="",K12="",L12="",M12="",N12="",O12="",P12=""),"",(H12+I12+J12+K12+L12+M12+N12+O12+P12)) | V12: =IF(COUNTA(H12:J12)>0,1,"") | W12: =IF(COUNTA(K12:M12)>0,1,"") | X12: =IF(COUNTA(N12:P12)>0,1,"") | Z12: =E12 -> 0 | AI12: =IF(AND(AB12="",AD12="",AF12=""),"",SUM(AB12,AD12,AF12)) | AJ12: =IF(AND(AC12="",AE12="",AG12=""),"",SUM(AC12,AE12,AG12)) | AL12: =AI12/R12 -> #VALUE! | AM12: =AJ12/R12 -> #VALUE!
R13: =COUNT(H13:P13) -> 0 | S13: =SUM(V13:X13) -> 0 | T13: =IF(AND(H13="",I13="",J13="",K13="",L13="",M13="",N13="",O13="",P13=""),"",(H13+I13+J13+K13+L13+M13+N13+O13+P13)) | V13: =IF(COUNTA(H13:J13)>0,1,"") | W13: =IF(COUNTA(K13:M13)>0,1,"") | X13: =IF(COUNTA(N13:P13)>0,1,"") | Z13: =E13 -> 0 | AI13: =IF(AND(AB13="",AD13="",AF13=""),"",SUM(AB13,AD13,AF13)) | AJ13: =IF(AND(AC13="",AE13="",AG13=""),"",SUM(AC13,AE13,AG13)) | AL13: =AI13/R13 -> #VALUE! | AM13: =AJ13/R13 -> #VALUE!
R14: =COUNT(H14:P14) -> 0 | S14: =SUM(V14:X14) -> 0 | T14: =IF(AND(H14="",I14="",J14="",K14="",L14="",M14="",N14="",O14="",P14=""),"",(H14+I14+J14+K14+L14+M14+N14+O14+P14)) | V14: =IF(COUNTA(H14:J14)>0,1,"") | W14: =IF(COUNTA(K14:M14)>0,1,"") | X14: =IF(COUNTA(N14:P14)>0,1,"") | Z14: =E14 -> 0 | AI14: =IF(AND(AB14="",AD14="",AF14=""),"",SUM(AB14,AD14,AF14)) | AJ14: =IF(AND(AC14="",AE14="",AG14=""),"",SUM(AC14,AE14,AG14)) | AL14: =AI14/R14 -> #VALUE! | AM14: =AJ14/R14 -> #VALUE!
R15: =COUNT(H15:P15) -> 0 | S15: =SUM(V15:X15) -> 0 | T15: =IF(AND(H15="",I15="",J15="",K15="",L15="",M15="",N15="",O15="",P15=""),"",(H15+I15+J15+K15+L15+M15+N15+O15+P15)) | V15: =IF(COUNTA(H15:J15)>0,1,"") | W15: =IF(COUNTA(K15:M15)>0,1,"") | X15: =IF(COUNTA(N15:P15)>0,1,"") | Z15: =E15 -> 0 | AI15: =IF(AND(AB15="",AD15="",AF15=""),"",SUM(AB15,AD15,AF15)) | AJ15: =IF(AND(AC15="",AE15="",AG15=""),"",SUM(AC15,AE15,AG15)) | AL15: =AI15/R15 -> #VALUE! | AM15: =AJ15/R15 -> #VALUE!
R16: =COUNT(H16:P16) -> 0 | S16: =SUM(V16:X16) -> 0 | T16: =IF(AND(H16="",I16="",J16="",K16="",L16="",M16="",N16="",O16="",P16=""),"",(H16+I16+J16+K16+L16+M16+N16+O16+P16)) | V16: =IF(COUNTA(H16:J16)>0,1,"") | W16: =IF(COUNTA(K16:M16)>0,1,"") | X16: =IF(COUNTA(N16:P16)>0,1,"") | Z16: =E16 -> 0 | AI16: =IF(AND(AB16="",AD16="",AF16=""),"",SUM(AB16,AD16,AF16)) | AJ16: =IF(AND(AC16="",AE16="",AG16=""),"",SUM(AC16,AE16,AG16)) | AL16: =AI16/R16 -> #VALUE! | AM16: =AJ16/R16 -> #VALUE!
R17: =COUNT(H17:P17) -> 0 | S17: =SUM(V17:X17) -> 0 | T17: =IF(AND(H17="",I17="",J17="",K17="",L17="",M17="",N17="",O17="",P17=""),"",(H17+I17+J17+K17+L17+M17+N17+O17+P17)) | V17: =IF(COUNTA(H17:J17)>0,1,"") | W17: =IF(COUNTA(K17:M17)>0,1,"") | X17: =IF(COUNTA(N17:P17)>0,1,"") | Z17: =E17 -> 0 | AI17: =IF(AND(AB17="",AD17="",AF17=""),"",SUM(AB17,AD17,AF17)) | AJ17: =IF(AND(AC17="",AE17="",AG17=""),"",SUM(AC17,AE17,AG17)) | AL17: =AI17/R17 -> #VALUE! | AM17: =AJ17/R17 -> #VALUE!
... R150: =COUNT(H150:P150) -> 0 | S150: =SUM(V150:X150) -> 0 | T150: =IF(AND(H150="",I150="",J150="",K150="",L150="",M150="",N150="",O150="",P150=""),"",(H150+I150+J150+K150+L150+M150+N150+O150+P150)) | V150: =IF(COUNTA(H150:J150)>0,1,"") | W150: =IF(COUNTA(K150:M150)>0,1,"") | X150: =IF(COUNTA(N150:P150)>0,1,"") | Z150: =E150 -> 0 | AI150: =IF(AND(AB150="",AD150="",AF150=""),"",SUM(AB150,AD150,AF150)) | AJ150: =IF(AND(AC150="",AE150="",AG150=""),"",SUM(AC150,AE150,AG150)) | AL150: =AI150/R150 -> #VALUE! | AM150: =AJ150/R150 -> #VALUE!
Z151: =E151 -> 0 | AI151: =IF(AND(AB151="",AD151="",AF151=""),"",SUM(AB151,AD151,AF151)) | AJ151: =IF(AND(AC151="",AE151="",AG151=""),"",SUM(AC151,AE151,AG151)) | AL151: =AI151/R151 -> #VALUE! | AM151: =AJ151/R151 -> #VALUE!
Z152: =E152 -> 0 | AI152: =IF(AND(AB152="",AD152="",AF152=""),"",SUM(AB152,AD152,AF152)) | AJ152: =IF(AND(AC152="",AE152="",AG152=""),"",SUM(AC152,AE152,AG152)) | AL152: =AI152/R152 -> #VALUE! | AM152: =AJ152/R152 -> #VALUE!
Z153: =E153 -> 0 | AI153: =IF(AND(AB153="",AD153="",AF153=""),"",SUM(AB153,AD153,AF153)) | AJ153: =IF(AND(AC153="",AE153="",AG153=""),"",SUM(AC153,AE153,AG153)) | AL153: =AI153/R153 -> #VALUE! | AM153: =AJ153/R153 -> #VALUE!
Z154: =E154 -> 0 | AI154: =IF(AND(AB154="",AD154="",AF154=""),"",SUM(AB154,AD154,AF154)) | AJ154: =IF(AND(AC154="",AE154="",AG154=""),"",SUM(AC154,AE154,AG154)) | AL154: =AI154/R154 -> #VALUE! | AM154: =AJ154/R154 -> #VALUE!
Z155: =E155 -> 0 | AI155: =IF(AND(AB155="",AD155="",AF155=""),"",SUM(AB155,AD155,AF155)) | AJ155: =IF(AND(AC155="",AE155="",AG155=""),"",SUM(AC155,AE155,AG155)) | AL155: =AI155/R155 -> #VALUE! | AM155: =AJ155/R155 -> #VALUE!
Z156: =E156 -> 0 | AI156: =IF(AND(AB156="",AD156="",AF156=""),"",SUM(AB156,AD156,AF156)) | AJ156: =IF(AND(AC156="",AE156="",AG156=""),"",SUM(AC156,AE156,AG156)) | AL156: =AI156/R156 -> #VALUE! | AM156: =AJ156/R156 -> #VALUE!
Z157: =E157 -> 0 | AI157: =IF(AND(AB157="",AD157="",AF157=""),"",SUM(AB157,AD157,AF157)) | AJ157: =IF(AND(AC157="",AE157="",AG157=""),"",SUM(AC157,AE157,AG157)) | AL157: =AI157/R157 -> #VALUE! | AM157: =AJ157/R157 -> #VALUE!
Z158: =E158 -> 0 | AI158: =IF(AND(AB158="",AD158="",AF158=""),"",SUM(AB158,AD158,AF158)) | AJ158: =IF(AND(AC158="",AE158="",AG158=""),"",SUM(AC158,AE158,AG158)) | AL158: =AI158/R158 -> #VALUE! | AM158: =AJ158/R158 -> #VALUE!
Z159: =E159 -> 0 | AI159: =IF(AND(AB159="",AD159="",AF159=""),"",SUM(AB159,AD159,AF159)) | AJ159: =IF(AND(AC159="",AE159="",AG159=""),"",SUM(AC159,AE159,AG159)) | AL159: =AI159/R159 -> #VALUE! | AM159: =AJ159/R159 -> #VALUE!
Z160: =E160 -> 0 | AI160: =IF(AND(AB160="",AD160="",AF160=""),"",SUM(AB160,AD160,AF160)) | AJ160: =IF(AND(AC160="",AE160="",AG160=""),"",SUM(AC160,AE160,AG160)) | AL160: =AI160/R160 -> #VALUE! | AM160: =AJ160/R160 -> #VALUE!
Z161: =E161 -> 0 | AI161: =IF(AND(AB161="",AD161="",AF161=""),"",SUM(AB161,AD161,AF161)) | AJ161: =IF(AND(AC161="",AE161="",AG161=""),"",SUM(AC161,AE161,AG161)) | AL161: =AI161/R161 -> #VALUE! | AM161: =AJ161/R161 -> #VALUE!
Z162: =E162 -> 0 | AI162: =IF(AND(AB162="",AD162="",AF162=""),"",SUM(AB162,AD162,AF162)) | AJ162: =IF(AND(AC162="",AE162="",AG162=""),"",SUM(AC162,AE162,AG162)) | AL162: =AI162/R162 -> #VALUE! | AM162: =AJ162/R162 -> #VALUE!
... Z301: =E301 -> 0 | AI301: =IF(AND(AB301="",AD301="",AF301=""),"",SUM(AB301,AD301,AF301)) | AJ301: =IF(AND(AC301="",AE301="",AG301=""),"",SUM(AC301,AE301,AG301)) | AL301: =AI301/R301 -> #VALUE! | AM301: =AJ301/R301 -> #VALUE!
AI302: =IF(AND(AB302="",AD302="",AF302=""),"",SUM(AB302,AD302,AF302)) | AJ302: =IF(AND(AC302="",AE302="",AG302=""),"",SUM(AC302,AE302,AG302))

Sheet SET 1 PLAYERS
B3: PLAYER NAME | E3: CLAN NAME | I3: EVENT KILLS | U3: DAMAGE | AB3: ACCURACY
B4: PROFESSIONAL | C4: IN - GAME | E4: TEAM NAME | F4: CLAN | G4: CLASS 1 | I4: DAY 1 | J4: DAY 2 | K4: DAY 3 | L4: DAY 4 | M4: DAY 5 | O4: MATCHES | P4: EVENTS | Q4: KILLS | R4: A.DAMAGE | S4: A.ACCURACY | U4: DAY 1 | V4: DAY 2 | W4: DAY 3 | X4: DAY 4 | Y4: DAY 5 | Z4: TOTAL | AA4: EVENT | AB4: DAY 1 | AC4: DAY 2 | AD4: DAY 3 | AE4: DAY 4 | AF4: DAY 5 | AG4: TOTAL | AH4: EVENT
B5: =IF(AND('ENTRY DATA'!C5=""),"",('ENTRY DATA'!C5)) | C5: =IF(AND('ENTRY DATA'!D5=""),"",('ENTRY DATA'!D5)) | E5: =IF(AND('ENTRY DATA'!F5=""),"",('ENTRY DATA'!F5)) | F5: =IF(AND('ENTRY DATA'!G5=""),"",('ENTRY DATA'!G5)) | G5: CLASS 1 | I5: =IF(AND('DAY 1'!M5=""),"",('DAY 1'!M5)) | J5: =IF(AND('DAY 2'!M5=""),"",('DAY 2'!M5)) | K5: =IF(AND('DAY 3'!M5=""),"",('DAY 3'!M5)) | L5: =IF(AND('DAY 4'!M5=""),"",('DAY 4'!M5)) | M5: =IF(AND('DAY 5'!M5=""),"",('DAY 5'!M5)) | O5: =SUM('DAY 1'!L5,'DAY 2'!L5,'DAY 3'!L5,'DAY 4'!L5,'DAY 5'!L5) -> 0 | P5: =IF(AND(I5="",J5="",K5="",L5="",M5=""),"",COUNT(I5,J5,K5,L5,M5)) | Q5: =IF(AND(I5="",J5="",K5="",L5="",M5=""),"",SUM(I5,J5,K5,L5,M5)) | R5: =IF(AND(Z5="",AA5=""),"",(Z5/AA5)) | S5: =IF(AND(AG5="",AH5=""),"",(AG5/AH5)) | U5: ='DAY 1'!Y5 | V5: ='DAY 2'!Y5 | W5: ='DAY 3'!Y5 | X5: ='DAY 4'!Y5 | Y5: ='DAY 5'!Y5 | Z5: =IF(AND(U5="",V5="",W5="",X5="",Y5=""),"",SUM(U5,V5,W5,X5,Y5)) | AA5: =IF(AND(U5="",V5="",W5="",X5="",Y5=""),"",COUNT(U5,V5,W5,X5,Y5)) | AB5: ='DAY 1'!Z5 | AC5: ='DAY 2'!Z5 | AD5: ='DAY 3'!Z5 | AE5: ='DAY 4'!Z5 | AF5: ='DAY 5'!Z5 | AG5: =IF(AND(AB5="",AC5="",AD5="",AE5="",AF5=""),"",SUM(AB5,AC5,AD5,AE5,AF5)) | AH5: =IF(AND(AB5="",AC5="",AD5="",AE5="",AF5=""),"",COUNT(AB5,AC5,AD5,AE5,AF5))
B6: =IF(AND('ENTRY DATA'!C6=""),"",('ENTRY DATA'!C6)) | C6: =IF(AND('ENTRY DATA'!D6=""),"",('ENTRY DATA'!D6)) | E6: =IF(AND('ENTRY DATA'!F6=""),"",('ENTRY DATA'!F6)) | F6: =IF(AND('ENTRY DATA'!G6=""),"",('ENTRY DATA'!G6)) | G6: CLASS 1 | I6: =IF(AND('DAY 1'!M6=""),"",('DAY 1'!M6)) | J6: =IF(AND('DAY 2'!M6=""),"",('DAY 2'!M6)) | K6: =IF(AND('DAY 3'!M6=""),"",('DAY 3'!M6)) | L6: =IF(AND('DAY 4'!M6=""),"",('DAY 4'!M6)) | M6: =IF(AND('DAY 5'!M6=""),"",('DAY 5'!M6)) | O6: =SUM('DAY 1'!L6,'DAY 2'!L6,'DAY 3'!L6,'DAY 4'!L6,'DAY 5'!L6) -> 0 | P6: =IF(AND(I6="",J6="",K6="",L6="",M6=""),"",COUNT(I6,J6,K6,L6,M6)) | Q6: =IF(AND(I6="",J6="",K6="",L6="",M6=""),"",SUM(I6,J6,K6,L6,M6)) | R6: =IF(AND(Z6="",AA6=""),"",(Z6/AA6)) | S6: =IF(AND(AG6="",AH6=""),"",(AG6/AH6)) | U6: ='DAY 1'!Y6 | V6: ='DAY 2'!Y6 | W6: ='DAY 3'!Y6 | X6: ='DAY 4'!Y6 | Y6: ='DAY 5'!Y6 | Z6: =IF(AND(U6="",V6="",W6="",X6="",Y6=""),"",SUM(U6,V6,W6,X6,Y6)) | AA6: =IF(AND(U6="",V6="",W6="",X6="",Y6=""),"",COUNT(U6,V6,W6,X6,Y6)) | AB6: ='DAY 1'!Z6 | AC6: ='DAY 2'!Z6 | AD6: ='DAY 3'!Z6 | AE6: ='DAY 4'!Z6 | AF6: ='DAY 5'!Z6 | AG6: =IF(AND(AB6="",AC6="",AD6="",AE6="",AF6=""),"",SUM(AB6,AC6,AD6,AE6,AF6)) | AH6: =IF(AND(AB6="",AC6="",AD6="",AE6="",AF6=""),"",COUNT(AB6,AC6,AD6,AE6,AF6))
B7: =IF(AND('ENTRY DATA'!C7=""),"",('ENTRY DATA'!C7)) | C7: =IF(AND('ENTRY DATA'!D7=""),"",('ENTRY DATA'!D7)) | E7: =IF(AND('ENTRY DATA'!F7=""),"",('ENTRY DATA'!F7)) | F7: =IF(AND('ENTRY DATA'!G7=""),"",('ENTRY DATA'!G7)) | G7: CLASS 1 | I7: =IF(AND('DAY 1'!M7=""),"",('DAY 1'!M7)) | J7: =IF(AND('DAY 2'!M7=""),"",('DAY 2'!M7)) | K7: =IF(AND('DAY 3'!M7=""),"",('DAY 3'!M7)) | L7: =IF(AND('DAY 4'!M7=""),"",('DAY 4'!M7)) | M7: =IF(AND('DAY 5'!M7=""),"",('DAY 5'!M7)) | O7: =SUM('DAY 1'!L7,'DAY 2'!L7,'DAY 3'!L7,'DAY 4'!L7,'DAY 5'!L7) -> 0 | P7: =IF(AND(I7="",J7="",K7="",L7="",M7=""),"",COUNT(I7,J7,K7,L7,M7)) | Q7: =IF(AND(I7="",J7="",K7="",L7="",M7=""),"",SUM(I7,J7,K7,L7,M7)) | R7: =IF(AND(Z7="",AA7=""),"",(Z7/AA7)) | S7: =IF(AND(AG7="",AH7=""),"",(AG7/AH7)) | U7: ='DAY 1'!Y7 | V7: ='DAY 2'!Y7 | W7: ='DAY 3'!Y7 | X7: ='DAY 4'!Y7 | Y7: ='DAY 5'!Y7 | Z7: =IF(AND(U7="",V7="",W7="",X7="",Y7=""),"",SUM(U7,V7,W7,X7,Y7)) | AA7: =IF(AND(U7="",V7="",W7="",X7="",Y7=""),"",COUNT(U7,V7,W7,X7,Y7)) | AB7: ='DAY 1'!Z7 | AC7: ='DAY 2'!Z7 | AD7: ='DAY 3'!Z7 | AE7: ='DAY 4'!Z7 | AF7: ='DAY 5'!Z7 | AG7: =IF(AND(AB7="",AC7="",AD7="",AE7="",AF7=""),"",SUM(AB7,AC7,AD7,AE7,AF7)) | AH7: =IF(AND(AB7="",AC7="",AD7="",AE7="",AF7=""),"",COUNT(AB7,AC7,AD7,AE7,AF7))
B8: =IF(AND('ENTRY DATA'!C8=""),"",('ENTRY DATA'!C8)) | C8: =IF(AND('ENTRY DATA'!D8=""),"",('ENTRY DATA'!D8)) | E8: =IF(AND('ENTRY DATA'!F8=""),"",('ENTRY DATA'!F8)) | F8: =IF(AND('ENTRY DATA'!G8=""),"",('ENTRY DATA'!G8)) | G8: CLASS 1 | I8: =IF(AND('DAY 1'!M8=""),"",('DAY 1'!M8)) | J8: =IF(AND('DAY 2'!M8=""),"",('DAY 2'!M8)) | K8: =IF(AND('DAY 3'!M8=""),"",('DAY 3'!M8)) | L8: =IF(AND('DAY 4'!M8=""),"",('DAY 4'!M8)) | M8: =IF(AND('DAY 5'!M8=""),"",('DAY 5'!M8)) | O8: =SUM('DAY 1'!L8,'DAY 2'!L8,'DAY 3'!L8,'DAY 4'!L8,'DAY 5'!L8) -> 0 | P8: =IF(AND(I8="",J8="",K8="",L8="",M8=""),"",COUNT(I8,J8,K8,L8,M8)) | Q8: =IF(AND(I8="",J8="",K8="",L8="",M8=""),"",SUM(I8,J8,K8,L8,M8)) | R8: =IF(AND(Z8="",AA8=""),"",(Z8/AA8)) | S8: =IF(AND(AG8="",AH8=""),"",(AG8/AH8)) | U8: ='DAY 1'!Y8 | V8: ='DAY 2'!Y8 | W8: ='DAY 3'!Y8 | X8: ='DAY 4'!Y8 | Y8: ='DAY 5'!Y8 | Z8: =IF(AND(U8="",V8="",W8="",X8="",Y8=""),"",SUM(U8,V8,W8,X8,Y8)) | AA8: =IF(AND(U8="",V8="",W8="",X8="",Y8=""),"",COUNT(U8,V8,W8,X8,Y8)) | AB8: ='DAY 1'!Z8 | AC8: ='DAY 2'!Z8 | AD8: ='DAY 3'!Z8 | AE8: ='DAY 4'!Z8 | AF8: ='DAY 5'!Z8 | AG8: =IF(AND(AB8="",AC8="",AD8="",AE8="",AF8=""),"",SUM(AB8,AC8,AD8,AE8,AF8)) | AH8: =IF(AND(AB8="",AC8="",AD8="",AE8="",AF8=""),"",COUNT(AB8,AC8,AD8,AE8,AF8))
B9: =IF(AND('ENTRY DATA'!C9=""),"",('ENTRY DATA'!C9)) | C9: =IF(AND('ENTRY DATA'!D9=""),"",('ENTRY DATA'!D9)) | E9: =IF(AND('ENTRY DATA'!F9=""),"",('ENTRY DATA'!F9)) | F9: =IF(AND('ENTRY DATA'!G9=""),"",('ENTRY DATA'!G9)) | G9: CLASS 1 | I9: =IF(AND('DAY 1'!M9=""),"",('DAY 1'!M9)) | J9: =IF(AND('DAY 2'!M9=""),"",('DAY 2'!M9)) | K9: =IF(AND('DAY 3'!M9=""),"",('DAY 3'!M9)) | L9: =IF(AND('DAY 4'!M9=""),"",('DAY 4'!M9)) | M9: =IF(AND('DAY 5'!M9=""),"",('DAY 5'!M9)) | O9: =SUM('DAY 1'!L9,'DAY 2'!L9,'DAY 3'!L9,'DAY 4'!L9,'DAY 5'!L9) -> 0 | P9: =IF(AND(I9="",J9="",K9="",L9="",M9=""),"",COUNT(I9,J9,K9,L9,M9)) | Q9: =IF(AND(I9="",J9="",K9="",L9="",M9=""),"",SUM(I9,J9,K9,L9,M9)) | R9: =IF(AND(Z9="",AA9=""),"",(Z9/AA9)) | S9: =IF(AND(AG9="",AH9=""),"",(AG9/AH9)) | U9: ='DAY 1'!Y9 | V9: ='DAY 2'!Y9 | W9: ='DAY 3'!Y9 | X9: ='DAY 4'!Y9 | Y9: ='DAY 5'!Y9 | Z9: =IF(AND(U9="",V9="",W9="",X9="",Y9=""),"",SUM(U9,V9,W9,X9,Y9)) | AA9: =IF(AND(U9="",V9="",W9="",X9="",Y9=""),"",COUNT(U9,V9,W9,X9,Y9)) | AB9: ='DAY 1'!Z9 | AC9: ='DAY 2'!Z9 | AD9: ='DAY 3'!Z9 | AE9: ='DAY 4'!Z9 | AF9: ='DAY 5'!Z9 | AG9: =IF(AND(AB9="",AC9="",AD9="",AE9="",AF9=""),"",SUM(AB9,AC9,AD9,AE9,AF9)) | AH9: =IF(AND(AB9="",AC9="",AD9="",AE9="",AF9=""),"",COUNT(AB9,AC9,AD9,AE9,AF9))
B10: =IF(AND('ENTRY DATA'!C10=""),"",('ENTRY DATA'!C10)) | C10: =IF(AND('ENTRY DATA'!D10=""),"",('ENTRY DATA'!D10)) | E10: =IF(AND('ENTRY DATA'!F10=""),"",('ENTRY DATA'!F10)) | F10: =IF(AND('ENTRY DATA'!G10=""),"",('ENTRY DATA'!G10)) | G10: CLASS 1 | I10: =IF(AND('DAY 1'!M10=""),"",('DAY 1'!M10)) | J10: =IF(AND('DAY 2'!M10=""),"",('DAY 2'!M10)) | K10: =IF(AND('DAY 3'!M10=""),"",('DAY 3'!M10)) | L10: =IF(AND('DAY 4'!M10=""),"",('DAY 4'!M10)) | M10: =IF(AND('DAY 5'!M10=""),"",('DAY 5'!M10)) | O10: =SUM('DAY 1'!L10,'DAY 2'!L10,'DAY 3'!L10,'DAY 4'!L10,'DAY 5'!L10) -> 0 | P10: =IF(AND(I10="",J10="",K10="",L10="",M10=""),"",COUNT(I10,J10,K10,L10,M10)) | Q10: =IF(AND(I10="",J10="",K10="",L10="",M10=""),"",SUM(I10,J10,K10,L10,M10)) | R10: =IF(AND(Z10="",AA10=""),"",(Z10/AA10)) | S10: =IF(AND(AG10="",AH10=""),"",(AG10/AH10)) | U10: ='DAY 1'!Y10 | V10: ='DAY 2'!Y10 | W10: ='DAY 3'!Y10 | X10: ='DAY 4'!Y10 | Y10: ='DAY 5'!Y10 | Z10: =IF(AND(U10="",V10="",W10="",X10="",Y10=""),"",SUM(U10,V10,W10,X10,Y10)) | AA10: =IF(AND(U10="",V10="",W10="",X10="",Y10=""),"",COUNT(U10,V10,W10,X10,Y10)) | AB10: ='DAY 1'!Z10 | AC10: ='DAY 2'!Z10 | AD10: ='DAY 3'!Z10 | AE10: ='DAY 4'!Z10 | AF10: ='DAY 5'!Z10 | AG10: =IF(AND(AB10="",AC10="",AD10="",AE10="",AF10=""),"",SUM(AB10,AC10,AD10,AE10,AF10)) | AH10: =IF(AND(AB10="",AC10="",AD10="",AE10="",AF10=""),"",COUNT(AB10,AC10,AD10,AE10,AF10))
B11: =IF(AND('ENTRY DATA'!C11=""),"",('ENTRY DATA'!C11)) | C11: =IF(AND('ENTRY DATA'!D11=""),"",('ENTRY DATA'!D11)) | E11: =IF(AND('ENTRY DATA'!F11=""),"",('ENTRY DATA'!F11)) | F11: =IF(AND('ENTRY DATA'!G11=""),"",('ENTRY DATA'!G11)) | G11: CLASS 1 | I11: =IF(AND('DAY 1'!M11=""),"",('DAY 1'!M11)) | J11: =IF(AND('DAY 2'!M11=""),"",('DAY 2'!M11)) | K11: =IF(AND('DAY 3'!M11=""),"",('DAY 3'!M11)) | L11: =IF(AND('DAY 4'!M11=""),"",('DAY 4'!M11)) | M11: =IF(AND('DAY 5'!M11=""),"",('DAY 5'!M11)) | O11: =SUM('DAY 1'!L11,'DAY 2'!L11,'DAY 3'!L11,'DAY 4'!L11,'DAY 5'!L11) -> 0 | P11: =IF(AND(I11="",J11="",K11="",L11="",M11=""),"",COUNT(I11,J11,K11,L11,M11)) | Q11: =IF(AND(I11="",J11="",K11="",L11="",M11=""),"",SUM(I11,J11,K11,L11,M11)) | R11: =IF(AND(Z11="",AA11=""),"",(Z11/AA11)) | S11: =IF(AND(AG11="",AH11=""),"",(AG11/AH11)) | U11: ='DAY 1'!Y11 | V11: ='DAY 2'!Y11 | W11: ='DAY 3'!Y11 | X11: ='DAY 4'!Y11 | Y11: ='DAY 5'!Y11 | Z11: =IF(AND(U11="",V11="",W11="",X11="",Y11=""),"",SUM(U11,V11,W11,X11,Y11)) | AA11: =IF(AND(U11="",V11="",W11="",X11="",Y11=""),"",COUNT(U11,V11,W11,X11,Y11)) | AB11: ='DAY 1'!Z11 | AC11: ='DAY 2'!Z11 | AD11: ='DAY 3'!Z11 | AE11: ='DAY 4'!Z11 | AF11: ='DAY 5'!Z11 | AG11: =IF(AND(AB11="",AC11="",AD11="",AE11="",AF11=""),"",SUM(AB11,AC11,AD11,AE11,AF11)) | AH11: =IF(AND(AB11="",AC11="",AD11="",AE11="",AF11=""),"",COUNT(AB11,AC11,AD11,AE11,AF11))
B12: =IF(AND('ENTRY DATA'!C12=""),"",('ENTRY DATA'!C12)) | C12: =IF(AND('ENTRY DATA'!D12=""),"",('ENTRY DATA'!D12)) | E12: =IF(AND('ENTRY DATA'!F12=""),"",('ENTRY DATA'!F12)) | F12: =IF(AND('ENTRY DATA'!G12=""),"",('ENTRY DATA'!G12)) | G12: CLASS 1 | I12: =IF(AND('DAY 1'!M12=""),"",('DAY 1'!M12)) | J12: =IF(AND('DAY 2'!M12=""),"",('DAY 2'!M12)) | K12: =IF(AND('DAY 3'!M12=""),"",('DAY 3'!M12)) | L12: =IF(AND('DAY 4'!M12=""),"",('DAY 4'!M12)) | M12: =IF(AND('DAY 5'!M12=""),"",('DAY 5'!M12)) | O12: =SUM('DAY 1'!L12,'DAY 2'!L12,'DAY 3'!L12,'DAY 4'!L12,'DAY 5'!L12) -> 0 | P12: =IF(AND(I12="",J12="",K12="",L12="",M12=""),"",COUNT(I12,J12,K12,L12,M12)) | Q12: =IF(AND(I12="",J12="",K12="",L12="",M12=""),"",SUM(I12,J12,K12,L12,M12)) | R12: =IF(AND(Z12="",AA12=""),"",(Z12/AA12)) | S12: =IF(AND(AG12="",AH12=""),"",(AG12/AH12)) | U12: ='DAY 1'!Y12 | V12: ='DAY 2'!Y12 | W12: ='DAY 3'!Y12 | X12: ='DAY 4'!Y12 | Y12: ='DAY 5'!Y12 | Z12: =IF(AND(U12="",V12="",W12="",X12="",Y12=""),"",SUM(U12,V12,W12,X12,Y12)) | AA12: =IF(AND(U12="",V12="",W12="",X12="",Y12=""),"",COUNT(U12,V12,W12,X12,Y12)) | AB12: ='DAY 1'!Z12 | AC12: ='DAY 2'!Z12 | AD12: ='DAY 3'!Z12 | AE12: ='DAY 4'!Z12 | AF12: ='DAY 5'!Z12 | AG12: =IF(AND(AB12="",AC12="",AD12="",AE12="",AF12=""),"",SUM(AB12,AC12,AD12,AE12,AF12)) | AH12: =IF(AND(AB12="",AC12="",AD12="",AE12="",AF12=""),"",COUNT(AB12,AC12,AD12,AE12,AF12))
B13: =IF(AND('ENTRY DATA'!C13=""),"",('ENTRY DATA'!C13)) | C13: =IF(AND('ENTRY DATA'!D13=""),"",('ENTRY DATA'!D13)) | E13: =IF(AND('ENTRY DATA'!F13=""),"",('ENTRY DATA'!F13)) | F13: =IF(AND('ENTRY DATA'!G13=""),"",('ENTRY DATA'!G13)) | G13: CLASS 1 | I13: =IF(AND('DAY 1'!M13=""),"",('DAY 1'!M13)) | J13: =IF(AND('DAY 2'!M13=""),"",('DAY 2'!M13)) | K13: =IF(AND('DAY 3'!M13=""),"",('DAY 3'!M13)) | L13: =IF(AND('DAY 4'!M13=""),"",('DAY 4'!M13)) | M13: =IF(AND('DAY 5'!M13=""),"",('DAY 5'!M13)) | O13: =SUM('DAY 1'!L13,'DAY 2'!L13,'DAY 3'!L13,'DAY 4'!L13,'DAY 5'!L13) -> 0 | P13: =IF(AND(I13="",J13="",K13="",L13="",M13=""),"",COUNT(I13,J13,K13,L13,M13)) | Q13: =IF(AND(I13="",J13="",K13="",L13="",M13=""),"",SUM(I13,J13,K13,L13,M13)) | R13: =IF(AND(Z13="",AA13=""),"",(Z13/AA13)) | S13: =IF(AND(AG13="",AH13=""),"",(AG13/AH13)) | U13: ='DAY 1'!Y13 | V13: ='DAY 2'!Y13 | W13: ='DAY 3'!Y13 | X13: ='DAY 4'!Y13 | Y13: ='DAY 5'!Y13 | Z13: =IF(AND(U13="",V13="",W13="",X13="",Y13=""),"",SUM(U13,V13,W13,X13,Y13)) | AA13: =IF(AND(U13="",V13="",W13="",X13="",Y13=""),"",COUNT(U13,V13,W13,X13,Y13)) | AB13: ='DAY 1'!Z13 | AC13: ='DAY 2'!Z13 | AD13: ='DAY 3'!Z13 | AE13: ='DAY 4'!Z13 | AF13: ='DAY 5'!Z13 | AG13: =IF(AND(AB13="",AC13="",AD13="",AE13="",AF13=""),"",SUM(AB13,AC13,AD13,AE13,AF13)) | AH13: =IF(AND(AB13="",AC13="",AD13="",AE13="",AF13=""),"",COUNT(AB13,AC13,AD13,AE13,AF13))
B14: =IF(AND('ENTRY DATA'!C14=""),"",('ENTRY DATA'!C14)) | C14: =IF(AND('ENTRY DATA'!D14=""),"",('ENTRY DATA'!D14)) | E14: =IF(AND('ENTRY DATA'!F14=""),"",('ENTRY DATA'!F14)) | F14: =IF(AND('ENTRY DATA'!G14=""),"",('ENTRY DATA'!G14)) | G14: CLASS 1 | I14: =IF(AND('DAY 1'!M14=""),"",('DAY 1'!M14)) | J14: =IF(AND('DAY 2'!M14=""),"",('DAY 2'!M14)) | K14: =IF(AND('DAY 3'!M14=""),"",('DAY 3'!M14)) | L14: =IF(AND('DAY 4'!M14=""),"",('DAY 4'!M14)) | M14: =IF(AND('DAY 5'!M14=""),"",('DAY 5'!M14)) | O14: =SUM('DAY 1'!L14,'DAY 2'!L14,'DAY 3'!L14,'DAY 4'!L14,'DAY 5'!L14) -> 0 | P14: =IF(AND(I14="",J14="",K14="",L14="",M14=""),"",COUNT(I14,J14,K14,L14,M14)) | Q14: =IF(AND(I14="",J14="",K14="",L14="",M14=""),"",SUM(I14,J14,K14,L14,M14)) | R14: =IF(AND(Z14="",AA14=""),"",(Z14/AA14)) | S14: =IF(AND(AG14="",AH14=""),"",(AG14/AH14)) | U14: ='DAY 1'!Y14 | V14: ='DAY 2'!Y14 | W14: ='DAY 3'!Y14 | X14: ='DAY 4'!Y14 | Y14: ='DAY 5'!Y14 | Z14: =IF(AND(U14="",V14="",W14="",X14="",Y14=""),"",SUM(U14,V14,W14,X14,Y14)) | AA14: =IF(AND(U14="",V14="",W14="",X14="",Y14=""),"",COUNT(U14,V14,W14,X14,Y14)) | AB14: ='DAY 1'!Z14 | AC14: ='DAY 2'!Z14 | AD14: ='DAY 3'!Z14 | AE14: ='DAY 4'!Z14 | AF14: ='DAY 5'!Z14 | AG14: =IF(AND(AB14="",AC14="",AD14="",AE14="",AF14=""),"",SUM(AB14,AC14,AD14,AE14,AF14)) | AH14: =IF(AND(AB14="",AC14="",AD14="",AE14="",AF14=""),"",COUNT(AB14,AC14,AD14,AE14,AF14))
B15: =IF(AND('ENTRY DATA'!C15=""),"",('ENTRY DATA'!C15)) | C15: =IF(AND('ENTRY DATA'!D15=""),"",('ENTRY DATA'!D15)) | E15: =IF(AND('ENTRY DATA'!F15=""),"",('ENTRY DATA'!F15)) | F15: =IF(AND('ENTRY DATA'!G15=""),"",('ENTRY DATA'!G15)) | G15: CLASS 1 | I15: =IF(AND('DAY 1'!M15=""),"",('DAY 1'!M15)) | J15: =IF(AND('DAY 2'!M15=""),"",('DAY 2'!M15)) | K15: =IF(AND('DAY 3'!M15=""),"",('DAY 3'!M15)) | L15: =IF(AND('DAY 4'!M15=""),"",('DAY 4'!M15)) | M15: =IF(AND('DAY 5'!M15=""),"",('DAY 5'!M15)) | O15: =SUM('DAY 1'!L15,'DAY 2'!L15,'DAY 3'!L15,'DAY 4'!L15,'DAY 5'!L15) -> 0 | P15: =IF(AND(I15="",J15="",K15="",L15="",M15=""),"",COUNT(I15,J15,K15,L15,M15)) | Q15: =IF(AND(I15="",J15="",K15="",L15="",M15=""),"",SUM(I15,J15,K15,L15,M15)) | R15: =IF(AND(Z15="",AA15=""),"",(Z15/AA15)) | S15: =IF(AND(AG15="",AH15=""),"",(AG15/AH15)) | U15: ='DAY 1'!Y15 | V15: ='DAY 2'!Y15 | W15: ='DAY 3'!Y15 | X15: ='DAY 4'!Y15 | Y15: ='DAY 5'!Y15 | Z15: =IF(AND(U15="",V15="",W15="",X15="",Y15=""),"",SUM(U15,V15,W15,X15,Y15)) | AA15: =IF(AND(U15="",V15="",W15="",X15="",Y15=""),"",COUNT(U15,V15,W15,X15,Y15)) | AB15: ='DAY 1'!Z15 | AC15: ='DAY 2'!Z15 | AD15: ='DAY 3'!Z15 | AE15: ='DAY 4'!Z15 | AF15: ='DAY 5'!Z15 | AG15: =IF(AND(AB15="",AC15="",AD15="",AE15="",AF15=""),"",SUM(AB15,AC15,AD15,AE15,AF15)) | AH15: =IF(AND(AB15="",AC15="",AD15="",AE15="",AF15=""),"",COUNT(AB15,AC15,AD15,AE15,AF15))
B16: =IF(AND('ENTRY DATA'!C16=""),"",('ENTRY DATA'!C16)) | C16: =IF(AND('ENTRY DATA'!D16=""),"",('ENTRY DATA'!D16)) | E16: =IF(AND('ENTRY DATA'!F16=""),"",('ENTRY DATA'!F16)) | F16: =IF(AND('ENTRY DATA'!G16=""),"",('ENTRY DATA'!G16)) | G16: CLASS 1 | I16: =IF(AND('DAY 1'!M16=""),"",('DAY 1'!M16)) | J16: =IF(AND('DAY 2'!M16=""),"",('DAY 2'!M16)) | K16: =IF(AND('DAY 3'!M16=""),"",('DAY 3'!M16)) | L16: =IF(AND('DAY 4'!M16=""),"",('DAY 4'!M16)) | M16: =IF(AND('DAY 5'!M16=""),"",('DAY 5'!M16)) | O16: =SUM('DAY 1'!L16,'DAY 2'!L16,'DAY 3'!L16,'DAY 4'!L16,'DAY 5'!L16) -> 0 | P16: =IF(AND(I16="",J16="",K16="",L16="",M16=""),"",COUNT(I16,J16,K16,L16,M16)) | Q16: =IF(AND(I16="",J16="",K16="",L16="",M16=""),"",SUM(I16,J16,K16,L16,M16)) | R16: =IF(AND(Z16="",AA16=""),"",(Z16/AA16)) | S16: =IF(AND(AG16="",AH16=""),"",(AG16/AH16)) | U16: ='DAY 1'!Y16 | V16: ='DAY 2'!Y16 | W16: ='DAY 3'!Y16 | X16: ='DAY 4'!Y16 | Y16: ='DAY 5'!Y16 | Z16: =IF(AND(U16="",V16="",W16="",X16="",Y16=""),"",SUM(U16,V16,W16,X16,Y16)) | AA16: =IF(AND(U16="",V16="",W16="",X16="",Y16=""),"",COUNT(U16,V16,W16,X16,Y16)) | AB16: ='DAY 1'!Z16 | AC16: ='DAY 2'!Z16 | AD16: ='DAY 3'!Z16 | AE16: ='DAY 4'!Z16 | AF16: ='DAY 5'!Z16 | AG16: =IF(AND(AB16="",AC16="",AD16="",AE16="",AF16=""),"",SUM(AB16,AC16,AD16,AE16,AF16)) | AH16: =IF(AND(AB16="",AC16="",AD16="",AE16="",AF16=""),"",COUNT(AB16,AC16,AD16,AE16,AF16))
